Workbook
Name ______new1: #REF!
Name _____new2: #REF!
Name _____Tax1: [1]Particulars!$A$1:$X$39
Name ____DAT1: [2]rental!#REF!
Name ____DAT10: [2]rental!#REF!
Name ____DAT11: [2]rental!#REF!
Name ____DAT12: #REF!
Name ____DAT13: #REF!
Name ____DAT14: #REF!
Name ____DAT2: [2]rental!#REF!
Name ____DAT3: [2]rental!#REF!
Name ____DAT4: [2]rental!#REF!
Name ____DAT5: [2]rental!#REF!
Name ____DAT6: [2]rental!#REF!
Name ____DAT7: [2]rental!#REF!
Name ____DAT8: [2]rental!#REF!
Name ____DAT9: [2]rental!#REF!
Name ___DAT1: [2]rental!#REF!
Name ___DAT10: [2]rental!#REF!
Name ___DAT11: [2]rental!#REF!
Name ___DAT12: #REF!
Name ___DAT13: #REF!
Name ___DAT14: #REF!
Name ___DAT2: [2]rental!#REF!
Name ___DAT3: [2]rental!#REF!
Name ___DAT4: [2]rental!#REF!
Name ___DAT5: [2]rental!#REF!
Name ___DAT6: [2]rental!#REF!
Name ___DAT7: [2]rental!#REF!
Name ___DAT8: [2]rental!#REF!
Name ___DAT9: [2]rental!#REF!
Name ___mds_view_data___: '[4]SSC Hong Kong'!#REF!
Name ___new1: #REF!
Name ___new2: #REF!
Name ___tax1: #REF!
Name ___tax2: #REF!
Name __DAT1: [2]rental!#REF!
Name __DAT10: [2]rental!#REF!
Name __DAT11: [2]rental!#REF!
Name __DAT12: #REF!
Name __DAT13: #REF!
Name __DAT14: #REF!
Name __DAT15: #REF!
Name __DAT2: [2]rental!#REF!
Name __DAT3: [2]rental!#REF!
Name __DAT4: [2]rental!#REF!
Name __DAT5: [2]rental!#REF!
Name __DAT6: [2]rental!#REF!
Name __DAT7: [2]rental!#REF!
Name __DAT8: [2]rental!#REF!
Name __DAT9: [2]rental!#REF!
Name __new1: #REF!
Name __new2: #REF!
Name __TAX1: '[8]Lei Wang'!$M$11:$O$19
Name __tax2: #REF!
Name __tax3: #REF!
Name _1: #N/A
Name _2355: #REF!
Name _DAT1: [2]rental!#REF!
Name _DAT10: [2]rental!#REF!

Sheet Check Result
F1: 0 | K1: 1
A2: Batch Name | B2: Legal Entity | C2: Payroll Group | D2: WEIN | E2: Check | F2: Diff | G2: Legal Last Name | H2: Legal First Name | I2: Legal full name | J2: Check | K2: Diff | L2: Preferred Name | M2: Hire Status | N2: Last Hired Date | O2: Check | P2: Diff | Q2: Last Employment Date | R2: Check | S2: Diff | T2: Business Department | U2: Check | V2: Diff | W2: Department Code | X2: Position Title | Y2: Check | Z2: Diff | AA2: Employee Cost Center | AB2: Cost Center Code | AC2: Check | AD2: Diff | AE2: Period | AF2: Is Overseas Employee | AG2: Years of Service | AH2: Monthly Base Pay | AI2: Check | AJ2: Diff | AK2: Base Pay 60001000 | AL2: Check | AM2: Diff | AN2: Salary Adj 60001000 | AO2: Check | AP2: Diff | AQ2: Monthly Base Pay(Temp) | AR2: Check | AS2: Diff | AT2: Base Pay(Temp) 60101000 | AU2: Check | AV2: Diff | AW2: Salary Adj (Temp) 60101000 | AX2: Monthly Rental Reimbursement | AY2: Rental Reimbursement 60001000 | AZ2: Rental Reimbursement Adj 60001000 | BA2: Monthly Transport Allowance | BB2: Check | BC2: Diff | BD2: Transport Allowance 60409960 | BE2: Check | BF2: Diff | BG2: Transport Allowance Adj 60409960 | BH2: Check | BI2: Diff | BJ2: Monthly Housing Allowance | BK2: Housing Allowance 60409960 | BL2: Housing Allowance Adj 60409960 | BM2: Total EAO Adj 60409960 | BN2: Check | BO2: Diff | BP2: Maternity Leave Payment 60001000 | BQ2: Check | BR2: Diff | BS2: Paternity Leave payment adjustment | BT2: Paternity Leave Payment 60001000 | BU2: Adjustment of Parental Paid Time Off(PPTO)payment | BV2: Paid Parental Time Off (PPTO) payment | BW2: Check | BX2: Diff | BY2: Sick Leave Payment 60001000 | BZ2: Check | CA2: Diff | CB2: Overtime Payment 99999999 | CC2: Annual Incentive 60201000 | CD2: Check | CE2: Diff | CF2: Sales Incentive (Quantitative) 21201000 | CG2: Check | CH2: Diff | CI2: Sales Incentive (Qualitative) 21201000 | CJ2: Check | CK2: Diff | CL2: Inspire Cash 60702000 | CM2: Check | CN2: Diff | CO2: Inspire Points (Gross Up) 60701000 | CP2: Check | CQ2: Diff | CR2: Goods & Services Differential 60601000 | CS2: Shares Dividend 60204001 | CT2: Check | CU2: Diff | CV2: Red Packet 69001000 | CW2: Check | CX2: Diff | CY2: Year End Bonus 60208000 | CZ2: Check | DA2: Diff | DB2: Gratuity Bonus 60208000 | DC2: Lump Sum Bonus 60409960 | DD2: Check | DE2: Diff | DF2: Referral Bonus 69001000 | DG2: Check | DH2: Diff | DI2: Sign On Bonus 60409960 | DJ2: Check | DK2: Diff | DL2: Retention Bonus 60409960 | DM2: Check | DN2: Diff | DO2: Other Bonus 99999999 | DP2: Check | DQ2: Diff | DR2: Employee Award 60208000 | DS2: AP President Club 60208000 | DT2: Manager of the Year Award 60208000 | DU2: Check | DV2: Diff | DW2: MD Award 60208000 | DX2: Check | DY2: Diff | DZ2: Other Rewards 99999999 | EA2: Check | EB2: Diff | EC2: Other Allowance 60409960 | ED2: Check | EE2: Diff | EF2: Education Benefits 99999999 | EG2: Flexible benefits | EH2: Check | EI2: Diff | EJ2: Pensions 99999999 | EK2: Untaken Annual Leave Payment 60409960 | EL2: Check | EM2: Diff | EN2: PIL ER to EE 60001000 | EO2: Check | EP2: Diff | EQ2: Back Pay 99999999 | ER2: Check | ES2: Diff | ET2: Gratuities 99999999 | EU2: Check | EV2: Diff | EW2: Termination Payment 99999999 | EX2: SP or LSP | EY2: Severance Payment 60404000 | EZ2: Check | FA2: Diff | FB2: Long Service Payment 60409960 | FC2: Check | FD2: Diff | FE2: IA Pay Split | FF2: Check | FG2: Diff | FH2: MPF Relevant Income | FI2: Check | FJ2: Diff | FK2: MPF VC Relevant Income | FL2: Check | FM2: Diff | FN2: ORSO Relevant Income | FO2: Check | FP2: Diff | FQ2: Employees' Compensation 60409960 | FR2: Non-taxable Item 21271000 | FS2: Medical Claim 60409960 | FT2: (Blank) | FU2: Optional Group Upgrade 21351000 | FV2: Check | FW2: Diff | FX2: Hypo Tax 60601000 | FY2: IA Pay Split by Host 60601000 | FZ2: No Pay Leave Deduction 60001000 | GA2: Check | GB2: Diff | GC2: NoPayLeaveCalculationBase_LastMonth | GD2: Overtaken Annual Leave Deduct 60001000 | GE2: PIL EE to ER 60001000 | GF2: Check | GG2: Diff | GH2: MPF EE VC Percentage | GI2: Check | GJ2: Diff | GK2: MPF ER VC Percentage_Input | GL2: MPF ER VC Percentage | GM2: Check | GN2: Diff | GO2: Percent Of ORSO EE | GP2: Check | GQ2: Diff | GR2: Percent Of ORSO ER | GS2: Check | GT2: Diff | GU2: ORSO EE Contribution Rate | GV2: ORSO ER Contribution Rate | GW2: ORSO EE 60801000 | GX2: Check | GY2: Diff | GZ2: ORSO EE Adj | HA2: ORSO ER Adj | HB2: Check | HC2: Diff | HD2: ORSO ER 60801000 | HE2: Check | HF2: Diff | HG2: MPF EE MC 21251000 | HH2: Check | HI2: Diff | HJ2: MPF EE VC 21251000 | HK2: Check | HL2: Diff | HM2: MPF ER MC 60801000 | HN2: Check | HO2: Diff | HP2: MPF ER VC 60801000 | HQ2: Check | HR2: Diff | HS2: Net Pay Adj Positive 21011900 | HT2: Net Pay Adj Negative 21011900 | HU2: Net Pay 21011900 | HV2: (Blank2) | HW2: InspirePoints | HX2: Check | HY2: Diff | HZ2: ECO Income | IA2: Total ECO Income_Pre12Month(Include current month) | IB2: Severance Payment over cap | IC2: Long Service Payment over cap | ID2: Retire Scheme Payment 99999999 | IE2: Salaries Tax Paid by Employer 60601000 | IF2: Share Option 99999999 | IG2: Year End Bonus Accrual 60208000 | IH2: EAO Accrual 60409960 | II2: Days_balance for accrual | IJ2: AL Accrual Base_Rewrite | IK2: Annual Leave Accrual 60409960 | IL2: ORSO Admin Fee 60801000 | IM2: Gratuity Bonus_Rewrite | IN2: ExchangeRate | IO2: AP President Club (US Dollars) | IP2: EAO Gross Income | IQ2: EAO Gross OT | IR2: EAO Days | IS2: PPTO EAO Rate input | IT2: Check | IU2: Diff | IV2: Contract End Date(Temp EE) | IW2: YearEndBonusStore-Dec | IX2: YearEndBonusStore-Unpaid | IY2: YEB Special Start Date | IZ2: YEB Special End Date | JA2: YEB Special Base | JB2: Current Year Hire Begin Date | JC2: Current Year Hire End Date | JD2: CycleCutOffDate_LastMonth | JE2: CycleCutOffDate | JF2: Remark | JG2: Pre-Transition YOS | JH2: Post-Transition YOS | JI2: Pre-Transition SP/LSP | JJ2: Post-Transition SP/LSP | JK2: Long Service Payment_New
A3: MSD Asia202510 | B3: MERCK SHARP & DOHME (ASIA) LIMITED | C3: MSD Asia | D3: 77777777 | E3: 77777777 | F3: TRUE | I3: GGG GG | J3: GGG GGG | K3: FALSE | M3: Active | N3: 2022-04-11 | T3: CAS-HONG KONG | X3: Sr SPEC-Cons,Digital Activation,HHDDA-AP | JG3: 3.05 | JH3: 0.5 | JI3: 0 | JJ3: 0 | JK3: 0

Sheet HC Check
A3: Row Labels | B3: Count of WEIN | C3: Check
A4: Active | B4: 8 | C4: =B11-B12-C13+C15 -> 8
A5: Grand Total | B5: 8
B10: Jul | C10: Aug
A11: Payroll HC | B11: 10 | C11: =GETPIVOTDATA("WEIN",$A$3,"Hire Status","Active") -> 8
A12: Current Month Terminated HC(included) | B12: 0 | C12: 0
A13: Current Month Terminated HC(OC) | B13: 0 | C13: 2
A14: Previous Month Terminated HC(included) | B14: 0 | C14: 3
A15: Current Month New HC | B15: 0 | C15: 0

Sheet Feb for check
M1: Workforce_CurrentMonth | P1: Workforce_CurrentMonth | S1: Workforce_CurrentMonth | V1: Workforce_CurrentMonth | AB1: Workforce_CurrentMonth | AD1: 4EE change salary, rounding issue | AE1: Formula | AH1: Formula | AO1: Allowance_CurrentMonth | AR1: Formula | AY1: Andrew Monthly 40000 | BB1: =SUM(BB3:BB132)-SUM(#REF!) -> #REF! | BD1: =SUM(#REF!)-SUM(BD3:BD132) -> #REF! | BK1: Formula: roundup | BR1: Offline: one time | BT1: Offline: IA | BX1: Formula | CA1: Formula | CD1: Formula | CG1: Offline:upgrade | CP1: Formula | CR1: Formula | CT1: Formula | CW1: Formula | CZ1: Formula | DC1: Formula | DF1: Formula | DI1: Ofline: Inspire | DJ1: =SUM(DI3:DI132)-SUM(#REF!) -> #REF!
A2: Batch Name | B2: Legal Entity | C2: Payroll Group | D2: WEIN | E2: Check LastPR | F2: Legal Last Name | G2: Legal First Name | H2: Legal full name | I2: Check | J2: Diff | K2: Preferred Name | L2: Hire Status | M2: Last Hired Date | N2: Check WR | O2: Diff. | P2: Business Department | Q2: Check WR | R2: Diff | S2: Position Title | T2: Check WR - Business Title | U2: Diff | V2: Cost Center Code | W2: Check WR | X2: Diff | Y2: Period | Z2: Is Overseas Employee | AA2: Years of Service | AB2: Monthly Base Pay | AC2: Check | AD2: Diff | AE2: Base Pay 60001000 | AF2: Check | AG2: Diff | AH2: Salary Adj 60001000 | AI2: Check | AJ2: Diff | AK2: Monthly Base Pay(Temp) | AL2: Check | AM2: Diff | AN2: Base Pay(Temp) 60101000 | AO2: Monthly Transport Allowance | AP2: Check | AQ2: Diff | AR2: Transport Allowance 60409960 | AS2: Check | AT2: Diff | AU2: Transport Allowance Adj 60409960 | AV2: Check | AW2: Monthly Housing Allowance | AX2: Check | AY2: Housing Allowance 60409960 | AZ2: Check | BA2: Total EAO Adj 60409960 | BB2: AL Days_LastM | BC2: Annual Leave calculation base-EAO rate_LastM | BD2: AL Days_CurrentM | BE2: Annual Leave calculation base-EAO rate_CurrentM | BF2: Check | BG2: Diff | BH2: Maternity Leave Payment 60001000 | BI2: Check | BJ2: Diff | BK2: Inspire Points (Gross Up) 60701000 | BL2: Check | BM2: Diff. | BN2: Year End Bonus 60208000 | BO2: Probation Expired | BP2: Check | BQ2: Diff. | BR2: Referral Bonus 69001000 | BS2: Check | BT2: Other Allowance 60409960 | BU2: Check | BV2: IA Pay Split | BW2: Check | BX2: MPF Relevant Income | BY2: Check | BZ2: Diff. | CA2: MPF VC Relevant Income | CB2: Check | CC2: Diff. | CD2: ORSO Relevant Income | CE2: Check | CF2: Diff. | CG2: Optional Group Upgrade 21351000 | CH2: Check | CI2: NoPayLeaveCalculationBase_LastMonth | CJ2: MPF EE VC Percentage | CK2: Check | CL2: MPF ER VC Percentage_Input | CM2: MPF ER VC Percentage | CN2: Percent Of ORSO EE | CO2: Percent Of ORSO ER | CP2: ORSO EE 60801000 | CQ2: Check | CR2: ORSO ER 60801000 | CS2: Check | CT2: MPF EE MC 21251000 | CU2: Check | CV2: Diff. | CW2: MPF EE VC 21251000 | CX2: Check | CY2: Diff. | CZ2: MPF ER MC 60801000 | DA2: Check | DB2: Diff. | DC2: MPF ER VC 60801000 | DD2: Check | DE2: Diff. | DF2: Net Pay 21011900 | DG2: Check | DH2: Diff. | DI2: InspirePoints | DJ2: Check | DK2: Diff. | DL2: ECO Income | DM2: Total ECO Income_Pre12Month(Include current month) | DN2: Year End Bonus Accrual 60208000 | DO2: EAO Accrual 60409960 | DP2: ORSO Admin Fee 60801000 | DQ2: EAO Gross Income | DR2: EAO Days | DS2: YearEndBonusStore-Unpaid | DT2: Current Year Hire Begin Date | DU2: Current Year Hire End Date | DV2: CycleCutOffDate_LastMonth | DW2: CycleCutOffDate
A3: MSD Asia202502 | B3: MERCK SHARP & DOHME (ASIA) LIMITED | C3: MSD Asia | D3: 51509685 | E3: =VLOOKUP(D3,#REF!,1,0) -> #REF! | F3: Kei Fong | G3: Wu | H3: =G3&" "&F3 -> Wu Kei Fong | I3: =VLOOKUP(D3,#REF!,9,0) -> #REF! | J3: =I3=H3 -> #REF! | K3: Wu | L3: Active | M3: 2025-02-06 | N3: =VLOOKUP(D3,#REF!,80,0) -> #REF! | O3: =N3-M3 -> #REF! | P3: HK Macau Team (DS) | Q3: =VLOOKUP(D3,#REF!,50,0) -> #REF! | R3: =Q3=P3 -> #REF! | S3: Customer Rep., Sales GHH | T3: =VLOOKUP(D3,#REF!,21,0) -> #REF! | U3: =T3=S3 -> #REF! | V3: 12630105 | W3: =VLOOKUP(D3,#REF!,51,0) -> #REF! | X3: =W3=V3 -> #REF! | Y3: 202502 | Z3: N | AA3: 0.06 | AB3: 22000 | AC3: =ROUND(VLOOKUP(D3,#REF!,59,0),0) -> #REF! | AD3: =AC3-AB3 -> #REF! | AE3: 18071.43 | AF3: =AB3*23/28 -> 18071.429 | AG3: =AF3-AE3 -> -0.0014285714 | AH3: 0 | AK3: 0 | AN3: 0 | AO3: 2500 | AP3: =IFERROR(VLOOKUP('Feb for check'!D3,#REF!,15,0),0) -> 0 | AQ3: =AP3-AO3 -> -2500 | AR3: 2053.57 | AS3: =AO3*23/28 -> 2053.5714 | AT3: =AS3-AR3 -> 0.0014285714 | AU3: 0 | AW3: 0 | AY3: 0 | BA3: 0 | BB3: =IFERROR(VLOOKUP(D3,#REF!,2,0),0) -> 0 | BC3: =MAX(VLOOKUP(D3,#REF!,13,0)-VLOOKUP(D3,#REF!,14,0),0) -> #REF! | BD3: =IFERROR(VLOOKUP(D3,#REF!,3,0),0) -> 0 | BE3: =MAX(VLOOKUP(D3,#REF!,22,0)-VLOOKUP(D3,#REF!,23,0),0) -> #REF! | BF3: =BB3*BC3+BD3*BE3 -> #REF! | BG3: =BF3-BA3 -> #REF! | BH3: 0 | BK3: 0 | BL3: =ROUNDUP(DI3/(1-0.17)*0.17,0) -> 0 | BM3: =BL3-BK3 -> 0 | BN3: 0 | BR3: 0 | BT3: 0 | BV3: 0 | BX3: 20125 | BY3: =SUM(AE3,AH3,AN3,AR3,AU3,AY3,BA3,BH3,BK3,BN3,BR3,BT3) -> 20125 | BZ3: =BY3-BX3 -> 0 | CA3: 18071.43 | CB3: =SUM(AE3,AH3,BA3,BH3) -> 18071.43 | CC3: =CB3-CA3 -> 0 | CD3: 0 | CG3: 0 | CI3: 0 | CJ3: 0 | CL3: 0 | CM3: 0.075 | CN3: 0 | CO3: 0 | CP3: 0 | CR3: 0 | CT3: 0 | CU3: =MIN(BX3*5%,1500) -> 1006.25 | CV3: 新员工，未满60天不缴纳 | CW3: 0 | CX3: =ROUND(CA3*CJ3,2) -> 0 | CY3: =CX3-CW3 -> 0 | CZ3: 0 | DA3: =MIN(BX3*5%,1500) -> 1006.25 | DB3: 新员工，未满60天不缴纳 | DC3: 0 | DD3: =MAX(ROUND(CA3*CM3-CZ3,2),0) -> 1355.36 | DE3: 新员工，未满60天不缴纳 | DF3: 20125 | DG3: =SUM(AE3,AH3,AN3,AR3,AU3,AY3,BA3,BH3,BK3,BN3,BR3,BT3,BV3,-CG3,-CP3,-CT3,-CW3) -> 20125 | DH3: =DG3-DF3 -> 0 | DI3: 0 | DJ3: =IFERROR(VLOOKUP(D3,#REF!,2,0),0) -> 0 | DK3: =DJ3-DI3 -> 0 | DL3: 18071.43 | DM3: 18071.43 | DN3: 1505.95 | DO3: 0 | DP3: 0 | DQ3: 20125 | DR3: 23 | DS3: 0 | DT3: 2025-02-06 | DU3: 2025-12-31 | DV3: 2025-01-10 | DW3: 2025-02-10
A4: MSD Asia202502 | B4: MERCK SHARP & DOHME (ASIA) LIMITED | C4: MSD Asia | D4: 51416201 | E4: =VLOOKUP(D4,#REF!,1,0) -> #REF! | F4: Tong | G4: Kin Yi | H4: =G4&" "&F4 -> Kin Yi Tong | I4: =VLOOKUP(D4,#REF!,9,0) -> #REF! | J4: =I4=H4 -> #REF! | K4: Gloria | L4: Active | M4: 2023-02-06 | N4: =VLOOKUP(D4,#REF!,80,0) -> #REF! | O4: =N4-M4 -> #REF! | P4: MRL HKG GCTO | Q4: =VLOOKUP(D4,#REF!,50,0) -> #REF! | R4: =Q4=P4 -> #REF! | S4: CRA | T4: =VLOOKUP(D4,#REF!,21,0) -> #REF! | U4: =T4=S4 -> #REF! | V4: 12630167 | W4: =VLOOKUP(D4,#REF!,51,0) -> #REF! | X4: =W4=V4 -> #REF! | Y4: 202502 | Z4: N | AA4: 2.06 | AB4: 38621 | AC4: =ROUND(VLOOKUP(D4,#REF!,59,0),0) -> #REF! | AD4: =AC4-AB4 -> #REF! | AE4: 38621 | AF4: =AB4 -> 38621 | AG4: =AF4-AE4 -> 0 | AH4: 0 | AK4: 0 | AN4: 0 | AO4: 0 | AP4: =IFERROR(VLOOKUP('Feb for check'!D4,#REF!,15,0),0) -> 0 | AQ4: =AP4-AO4 -> 0 | AR4: 0 | AS4: =AO4 -> 0 | AT4: =AS4-AR4 -> 0 | AU4: 0 | AW4: 0 | AY4: 0 | BA4: 1242.76 | BB4: =IFERROR(VLOOKUP(D4,#REF!,2,0),0) -> 0 | BC4: =MAX(VLOOKUP(D4,#REF!,13,0)-VLOOKUP(D4,#REF!,14,0),0) -> #REF! | BD4: =IFERROR(VLOOKUP(D4,#REF!,3,0),0) -> 0 | BE4: =MAX(VLOOKUP(D4,#REF!,22,0)-VLOOKUP(D4,#REF!,23,0),0) -> #REF! | BF4: =BB4*BC4+BD4*BE4 -> #REF! | BG4: =BF4-BA4 -> #REF! | BH4: 0 | BK4: 110 | BL4: =ROUNDUP(DI4/(1-0.17)*0.17,0) -> 110 | BM4: =BL4-BK4 -> 0 | BN4: 0 | BR4: 0 | BT4: 0 | BV4: 0 | BX4: 39973.76 | BY4: =SUM(AE4,AH4,AN4,AR4,AU4,AY4,BA4,BH4,BK4,BN4,BR4,BT4) -> 39973.76 | BZ4: =BY4-BX4 -> 0 | CA4: 39863.76 | CB4: =SUM(AE4,AH4,BA4,BH4) -> 39863.76 | CC4: =CB4-CA4 -> 0 | CD4: 0 | CG4: 0 | CI4: 1269.7315 | CJ4: 0 | CL4: 0 | CM4: 0.075 | CN4: 0 | CO4: 0 | CP4: 0 | CR4: 0 | CT4: 1500 | CU4: =MIN(BX4*5%,1500) -> 1500 | CV4: =CU4-CT4 -> 0 | CW4: 0 | CX4: =ROUND(CA4*CJ4,2) -> 0 | CY4: =CX4-CW4 -> 0 | CZ4: 1500 | DA4: =MIN(BX4*5%,1500) -> 1500 | DB4: =DA4-CZ4 -> 0 | DC4: 1489.78 | DD4: =MAX(ROUND(CA4*CM4-CZ4,2),0) -> 1489.78 | DE4: =DD4-DC4 -> 0 | DF4: 38473.76 | DG4: =SUM(AE4,AH4,AN4,AR4,AU4,AY4,BA4,BH4,BK4,BN4,BR4,BT4,BV4,-CG4,-CP4,-CT4,-CW4) -> 38473.76 | DH4: =DG4-DF4 -> 0 | DI4: 536.21 | DJ4: =IFERROR(VLOOKUP(D4,#REF!,2,0),0) -> 0 | DK4: =DJ4-DI4 -> -536.21 | DL4: 39973.76 | DM4: 617103.87 | DN4: 3218.42 | DO4: 1242.76 | DP4: 0 | DQ4: 39863.76 | DR4: 28 | DS4: 0 | DT4: 2025-01-01 | DU4: 2025-12-31 | DV4: 2025-01-10 | DW4: 2025-02-10
A5: MSD Asia202502 | B5: MERCK SHARP & DOHME (ASIA) LIMITED | C5: MSD Asia | D5: 51425942 | E5: =VLOOKUP(D5,#REF!,1,0) -> #REF! | F5: Ho | G5: Yuk Kam | H5: =G5&" "&F5 -> Yuk Kam Ho | I5: =VLOOKUP(D5,#REF!,9,0) -> #REF! | J5: =I5=H5 -> #REF! | K5: Kana | L5: Active | M5: 2022-04-11 | N5: =VLOOKUP(D5,#REF!,80,0) -> #REF! | O5: =N5-M5 -> #REF! | P5: CAS-HONG KONG | Q5: =VLOOKUP(D5,#REF!,50,0) -> #REF! | R5: =Q5=P5 -> #REF! | S5: Sr Specialist - Consumer, Digital Activation, HHDDA- Asia Pacific | T5: =VLOOKUP(D5,#REF!,21,0) -> #REF! | U5: =T5=S5 -> #REF! | V5: 12630420 | W5: =VLOOKUP(D5,#REF!,51,0) -> #REF! | X5: =W5=V5 -> #REF! | Y5: 202502 | Z5: N | AA5: 2.89 | AB5: 59376.08 | AC5: =ROUND(VLOOKUP(D5,#REF!,59,0),0) -> #REF! | AD5: =AC5-AB5 -> #REF! | AE5: 61105.16 | AF5: =AB5+AB5-VLOOKUP(D5,#REF!,14,0) -> #REF! | AG5: =AF5-AE5 -> #REF! | AH5: 0 | AK5: 0 | AN5: 0 | AO5: 0 | AP5: =IFERROR(VLOOKUP('Feb for check'!D5,#REF!,15,0),0) -> 0 | AQ5: =AP5-AO5 -> 0 | AR5: 0 | AS5: =AO5 -> 0 | AT5: =AS5-AR5 -> 0 | AU5: 0 | AW5: 0 | AY5: 0 | BA5: 0 | BB5: =IFERROR(VLOOKUP(D5,#REF!,2,0),0) -> 0 | BC5: =MAX(VLOOKUP(D5,#REF!,13,0)-VLOOKUP(D5,#REF!,14,0),0) -> #REF! | BD5: =IFERROR(VLOOKUP(D5,#REF!,3,0),0) -> 0 | BE5: =MAX(VLOOKUP(D5,#REF!,22,0)-VLOOKUP(D5,#REF!,23,0),0) -> #REF! | BF5: =BB5*BC5+BD5*BE5 -> #REF! | BG5: =BF5-BA5 -> #REF! | BH5: 0 | BK5: 0 | BL5: =ROUNDUP(DI5/(1-0.17)*0.17,0) -> 0 | BM5: =BL5-BK5 -> 0 | BN5: 0 | BR5: 0 | BT5: 0 | BV5: 0 | BX5: 61105.16 | BY5: =SUM(AE5,AH5,AN5,AR5,AU5,AY5,BA5,BH5,BK5,BN5,BR5,BT5) -> 61105.16 | BZ5: =BY5-BX5 -> 0 | CA5: 61105.16 | CB5: =SUM(AE5,AH5,BA5,BH5) -> 61105.16 | CC5: =CB5-CA5 -> 0 | CD5: 0 | CG5: 0 | CI5: 1895.2438 | CJ5: 0 | CL5: 0 | CM5: 0.075 | CN5: 0 | CO5: 0 | CP5: 0 | CR5: 0 | CT5: 1500 | CU5: =MIN(BX5*5%,1500) -> 1500 | CV5: =CU5-CT5 -> 0 | CW5: 0 | CX5: =ROUND(CA5*CJ5,2) -> 0 | CY5: =CX5-CW5 -> 0 | CZ5: 1500 | DA5: =MIN(BX5*5%,1500) -> 1500 | DB5: =DA5-CZ5 -> 0 | DC5: 3082.89 | DD5: =MAX(ROUND(CA5*CM5-CZ5,2),0) -> 3082.89 | DE5: =DD5-DC5 -> 0 | DF5: 59605.16 | DG5: =SUM(AE5,AH5,AN5,AR5,AU5,AY5,BA5,BH5,BK5,BN5,BR5,BT5,BV5,-CG5,-CP5,-CT5,-CW5) -> 59605.16 | DH5: =DG5-DF5 -> 0 | DI5: 0 | DJ5: =IFERROR(VLOOKUP(D5,#REF!,2,0),0) -> 0 | DK5: =DJ5-DI5 -> 0 | DL5: 61105.16 | DM5: 1027658.7 | DN5: 4948.01 | DO5: 0 | DP5: 0 | DQ5: 61105.16 | DR5: 28 | DS5: 0 | DT5: 2025-01-01 | DU5: 2025-12-31 | DV5: 2025-01-10 | DW5: 2025-02-10
A6: MSD Asia202502 | B6: MERCK SHARP & DOHME (ASIA) LIMITED | C6: MSD Asia | D6: 33900515 | E6: =VLOOKUP(D6,#REF!,1,0) -> #REF! | F6: Mak | G6: Wai Wah | H6: =G6&" "&F6 -> Wai Wah Mak | I6: =VLOOKUP(D6,#REF!,9,0) -> #REF! | J6: =I6=H6 -> #REF! | K6: Norris | L6: Active | M6: 2021-04-19 | N6: =VLOOKUP(D6,#REF!,80,0) -> #REF! | O6: =N6-M6 -> #REF! | P6: HK VACCINE (MA) | Q6: =VLOOKUP(D6,#REF!,50,0) -> #REF! | R6: =Q6=P6 -> #REF! | S6: Business Unit Director, Vaccines | T6: =VLOOKUP(D6,#REF!,21,0) -> #REF! | U6: =T6=S6 -> #REF! | V6: 12630102 | W6: =VLOOKUP(D6,#REF!,51,0) -> #REF! | X6: =W6=V6 -> #REF! | Y6: 202502 | Z6: N | AA6: 20.52 | AB6: 114700 | AC6: =ROUND(VLOOKUP(D6,#REF!,59,0),0) -> #REF! | AD6: =AC6-AB6 -> #REF! | AE6: 114700 | AF6: =AB6 -> 114700 | AG6: =AF6-AE6 -> 0 | AH6: 0 | AK6: 0 | AN6: 0 | AO6: 0 | AP6: =IFERROR(VLOOKUP('Feb for check'!D6,#REF!,15,0),0) -> 0 | AQ6: =AP6-AO6 -> 0 | AR6: 0 | AS6: =AO6 -> 0 | AT6: =AS6-AR6 -> 0 | AU6: 0 | AW6: 0 | AY6: 0 | BA6: 0 | BB6: =IFERROR(VLOOKUP(D6,#REF!,2,0),0) -> 0 | BC6: =MAX(VLOOKUP(D6,#REF!,13,0)-VLOOKUP(D6,#REF!,14,0),0) -> #REF! | BD6: =IFERROR(VLOOKUP(D6,#REF!,3,0),0) -> 0 | BE6: =MAX(VLOOKUP(D6,#REF!,22,0)-VLOOKUP(D6,#REF!,23,0),0) -> #REF! | BF6: =BB6*BC6+BD6*BE6 -> #REF! | BG6: =BF6-BA6 -> #REF! | BH6: 0 | BK6: 1834 | BL6: =ROUNDUP(DI6/(1-0.17)*0.17,0) -> 1834 | BM6: =BL6-BK6 -> 0 | BN6: 0 | BR6: 0 | BT6: 0 | BV6: 0 | BX6: 116534 | BY6: =SUM(AE6,AH6,AN6,AR6,AU6,AY6,BA6,BH6,BK6,BN6,BR6,BT6) -> 116534 | BZ6: =BY6-BX6 -> 0 | CA6: 114700 | CB6: =SUM(AE6,AH6,BA6,BH6) -> 114700 | CC6: =CB6-CA6 -> 0 | CD6: 0 | CG6: 0 | CI6: 3770.9589 | CJ6: 0.05 | CL6: 0 | CM6: 0.1 | CN6: 0 | CO6: 0 | CP6: 0 | CR6: 0 | CT6: 1500 | CU6: =MIN(BX6*5%,1500) -> 1500 | CV6: =CU6-CT6 -> 0 | CW6: 5735 | CX6: =ROUND(CA6*CJ6,2) -> 5735 | CY6: =CX6-CW6 -> 0 | CZ6: 1500 | DA6: =MIN(BX6*5%,1500) -> 1500 | DB6: =DA6-CZ6 -> 0 | DC6: 9970 | DD6: =MAX(ROUND(CA6*CM6-CZ6,2),0) -> 9970 | DE6: =DD6-DC6 -> 0 | DF6: 109299 | DG6: =SUM(AE6,AH6,AN6,AR6,AU6,AY6,BA6,BH6,BK6,BN6,BR6,BT6,BV6,-CG6,-CP6,-CT6,-CW6) -> 109299 | DH6: =DG6-DF6 -> 0 | DI6: 8951.7 | DJ6: =IFERROR(VLOOKUP(D6,#REF!,2,0),0) -> 0 | DK6: =DJ6-DI6 -> -8951.7 | DL6: 116534 | DM6: 2098915.5 | DN6: 9558.33 | DO6: 0 | DP6: 0 | DQ6: 114700 | DR6: 28 | DS6: 0 | DT6: 2025-01-01 | DU6: 2025-12-31 | DV6: 2025-01-10 | DW6: 2025-02-10
A7: MSD Asia202502 | B7: MERCK SHARP & DOHME (ASIA) LIMITED | C7: MSD Asia | D7: 51443582 | E7: =VLOOKUP(D7,#REF!,1,0) -> #REF! | F7: Lam | G7: PO KIN JONATHAN | H7: =G7&" "&F7 -> PO KIN JONATHAN Lam | I7: =VLOOKUP(D7,#REF!,9,0) -> #REF! | J7: =I7=H7 -> #REF! | K7: Jonathan | L7: Active | M7: 2024-09-30 | N7: =VLOOKUP(D7,#REF!,80,0) -> #REF! | O7: =N7-M7 -> #REF! | P7: AH SALES ADMIN | Q7: =VLOOKUP(D7,#REF!,50,0) -> #REF! | R7: =Q7=P7 -> #REF! | S7: Assoc. Spclst., Regulatory Affairs | T7: =VLOOKUP(D7,#REF!,21,0) -> #REF! | U7: =T7=S7 -> #REF! | V7: 12630417 | W7: =VLOOKUP(D7,#REF!,51,0) -> #REF! | X7: =W7=V7 -> #REF! | Y7: 202502 | Z7: N | AA7: 0.42 | AB7: 26520 | AC7: =ROUND(VLOOKUP(D7,#REF!,59,0),0) -> #REF! | AD7: =AC7-AB7 -> #REF! | AE7: 26520 | AF7: =AB7 -> 26520 | AG7: =AF7-AE7 -> 0 | AH7: 0 | AK7: 0 | AN7: 0 | AO7: 0 | AP7: =IFERROR(VLOOKUP('Feb for check'!D7,#REF!,15,0),0) -> 0 | AQ7: =AP7-AO7 -> 0 | AR7: 0 | AS7: =AO7 -> 0 | AT7: =AS7-AR7 -> 0 | AU7: 0 | AW7: 0 | AY7: 0 | BA7: 0 | BB7: =IFERROR(VLOOKUP(D7,#REF!,2,0),0) -> 0 | BC7: =MAX(VLOOKUP(D7,#REF!,13,0)-VLOOKUP(D7,#REF!,14,0),0) -> #REF! | BD7: =IFERROR(VLOOKUP(D7,#REF!,3,0),0) -> 0 | BE7: =MAX(VLOOKUP(D7,#REF!,22,0)-VLOOKUP(D7,#REF!,23,0),0) -> #REF! | BF7: =BB7*BC7+BD7*BE7 -> #REF! | BG7: =BF7-BA7 -> #REF! | BH7: 0 | BK7: 0 | BL7: =ROUNDUP(DI7/(1-0.17)*0.17,0) -> 0 | BM7: =BL7-BK7 -> 0 | BN7: 0 | BR7: 0 | BT7: 0 | BV7: 0 | BX7: 26520 | BY7: =SUM(AE7,AH7,AN7,AR7,AU7,AY7,BA7,BH7,BK7,BN7,BR7,BT7) -> 26520 | BZ7: =BY7-BX7 -> 0 | CA7: 26520 | CB7: =SUM(AE7,AH7,BA7,BH7) -> 26520 | CC7: =CB7-CA7 -> 0 | CD7: 0 | CG7: 0 | CI7: 871.8904 | CJ7: 0 | CL7: 0 | CM7: 0.075 | CN7: 0 | CO7: 0 | CP7: 0 | CR7: 0 | CT7: 1326 | CU7: =MIN(BX7*5%,1500) -> 1326 | CV7: =CU7-CT7 -> 0 | CW7: 0 | CX7: =ROUND(CA7*CJ7,2) -> 0 | CY7: =CX7-CW7 -> 0 | CZ7: 1326 | DA7: =MIN(BX7*5%,1500) -> 1326 | DB7: =DA7-CZ7 -> 0 | DC7: 663 | DD7: =MAX(ROUND(CA7*CM7-CZ7,2),0) -> 663 | DE7: =DD7-DC7 -> 0 | DF7: 25194 | DG7: =SUM(AE7,AH7,AN7,AR7,AU7,AY7,BA7,BH7,BK7,BN7,BR7,BT7,BV7,-CG7,-CP7,-CT7,-CW7) -> 25194 | DH7: =DG7-DF7 -> 0 | DI7: 0 | DJ7: =IFERROR(VLOOKUP(D7,#REF!,2,0),0) -> 0 | DK7: =DJ7-DI7 -> 0 | DL7: 26520 | DM7: 140697.02 | DN7: 2210 | DO7: 0 | DP7: 0 | DQ7: 26520 | DR7: 28 | DS7: 0 | DT7: 2025-01-01 | DU7: 2025-12-31 | DV7: 2025-01-10 | DW7: 2025-02-10
A8: MSD Asia202502 | B8: MERCK SHARP & DOHME (ASIA) LIMITED | C8: MSD Asia | D8: 51317350 | E8: =VLOOKUP(D8,#REF!,1,0) -> #REF! | F8: Chau | G8: Wing Yan Rene | H8: =G8&" "&F8 -> Wing Yan Rene Chau | I8: =VLOOKUP(D8,#REF!,9,0) -> #REF! | J8: =I8=H8 -> #REF! | K8: Rene | L8: Active | M8: 2018-08-01 | N8: =VLOOKUP(D8,#REF!,80,0) -> #REF! | O8: =N8-M8 -> #REF! | P8: MRL HKG GMVC | Q8: =VLOOKUP(D8,#REF!,50,0) -> #REF! | R8: =Q8=P8 -> #REF! | S8: Dir, V&I GMVC, AP HUB, Scientific Ops, Team Lead | T8: =VLOOKUP(D8,#REF!,21,0) -> #REF! | U8: =T8=S8 -> #REF! | V8: 12630364 | W8: =VLOOKUP(D8,#REF!,51,0) -> #REF! | X8: =W8=V8 -> #REF! | Y8: 202502 | Z8: N | AA8: 6.58 | AB8: 130325 | AC8: =ROUND(VLOOKUP(D8,#REF!,59,0),0) -> #REF! | AD8: =AC8-AB8 -> #REF! | AE8: 130325 | AF8: =AB8 -> 130325 | AG8: =AF8-AE8 -> 0 | AH8: 0 | AK8: 0 | AN8: 0 | AO8: 0 | AP8: =IFERROR(VLOOKUP('Feb for check'!D8,#REF!,15,0),0) -> 0 | AQ8: =AP8-AO8 -> 0 | AR8: 0 | AS8: =AO8 -> 0 | AT8: =AS8-AR8 -> 0 | AU8: 0 | AW8: 0 | AY8: 0 | BA8: 0 | BB8: =IFERROR(VLOOKUP(D8,#REF!,2,0),0) -> 0 | BC8: =MAX(VLOOKUP(D8,#REF!,13,0)-VLOOKUP(D8,#REF!,14,0),0) -> #REF! | BD8: =IFERROR(VLOOKUP(D8,#REF!,3,0),0) -> 0 | BE8: =MAX(VLOOKUP(D8,#REF!,22,0)-VLOOKUP(D8,#REF!,23,0),0) -> #REF! | BF8: =BB8*BC8+BD8*BE8 -> #REF! | BG8: =BF8-BA8 -> #REF! | BH8: 0 | BK8: 0 | BL8: =ROUNDUP(DI8/(1-0.17)*0.17,0) -> 0 | BM8: =BL8-BK8 -> 0 | BN8: 0 | BR8: 0 | BT8: 0 | BV8: 0 | BX8: 130325 | BY8: =SUM(AE8,AH8,AN8,AR8,AU8,AY8,BA8,BH8,BK8,BN8,BR8,BT8) -> 130325 | BZ8: =BY8-BX8 -> 0 | CA8: 130325 | CB8: =SUM(AE8,AH8,BA8,BH8) -> 130325 | CC8: =CB8-CA8 -> 0 | CD8: 0 | CG8: 0 | CI8: 4284.6575 | CJ8: 0 | CL8: 0 | CM8: 0.075 | CN8: 0 | CO8: 0 | CP8: 0 | CR8: 0 | CT8: 1500 | CU8: =MIN(BX8*5%,1500) -> 1500 | CV8: =CU8-CT8 -> 0 | CW8: 0 | CX8: =ROUND(CA8*CJ8,2) -> 0 | CY8: =CX8-CW8 -> 0 | CZ8: 1500 | DA8: =MIN(BX8*5%,1500) -> 1500 | DB8: =DA8-CZ8 -> 0 | DC8: 8274.38 | DD8: =MAX(ROUND(CA8*CM8-CZ8,2),0) -> 8274.38 | DE8: =DD8-DC8 -> 0 | DF8: 128825 | DG8: =SUM(AE8,AH8,AN8,AR8,AU8,AY8,BA8,BH8,BK8,BN8,BR8,BT8,BV8,-CG8,-CP8,-CT8,-CW8) -> 128825 | DH8: =DG8-DF8 -> 0 | DI8: 0 | DJ8: =IFERROR(VLOOKUP(D8,#REF!,2,0),0) -> 0 | DK8: =DJ8-DI8 -> 0 | DL8: 130325 | DM8: 2325997 | DN8: 10860.42 | DO8: 0 | DP8: 0 | DQ8: 130325 | DR8: 28 | DS8: 0 | DT8: 2025-01-01 | DU8: 2025-12-31 | DV8: 2025-01-10 | DW8: 2025-02-10
A9: MSD Asia202502 | B9: MERCK SHARP & DOHME (ASIA) LIMITED | C9: MSD Asia | D9: 51026180 | E9: =VLOOKUP(D9,#REF!,1,0) -> #REF! | F9: Leung | G9: Kin Yue Francis | H9: =G9&" "&F9 -> Kin Yue Francis Leung | I9: =VLOOKUP(D9,#REF!,9,0) -> #REF! | J9: =I9=H9 -> #REF! | K9: Francis | L9: Active | M9: 2014-08-25 | N9: =VLOOKUP(D9,#REF!,80,0) -> #REF! | O9: =N9-M9 -> #REF! | P9: MRL HKG GCTO | Q9: =VLOOKUP(D9,#REF!,50,0) -> #REF! | R9: =Q9=P9 -> #REF! | S9: CRD | T9: =VLOOKUP(D9,#REF!,21,0) -> #REF! | U9: =T9=S9 -> #REF! | V9: 12630167 | W9: =VLOOKUP(D9,#REF!,51,0) -> #REF! | X9: =W9=V9 -> #REF! | Y9: 202502 | Z9: N | AA9: 10.52 | AB9: 97000 | AC9: =ROUND(VLOOKUP(D9,#REF!,59,0),0) -> #REF! | AD9: =AC9-AB9 -> #REF! | AE9: 97000 | AF9: =AB9 -> 97000 | AG9: =AF9-AE9 -> 0 | AH9: 0 | AK9: 0 | AN9: 0 | AO9: 0 | AP9: =IFERROR(VLOOKUP('Feb for check'!D9,#REF!,15,0),0) -> 0 | AQ9: =AP9-AO9 -> 0 | AR9: 0 | AS9: =AO9 -> 0 | AT9: =AS9-AR9 -> 0 | AU9: 0 | AW9: 0 | AY9: 0 | BA9: 1562.38 | BB9: =IFERROR(VLOOKUP(D9,#REF!,2,0),0) -> 0 | BC9: =MAX(VLOOKUP(D9,#REF!,13,0)-VLOOKUP(D9,#REF!,14,0),0) -> #REF! | BD9: =IFERROR(VLOOKUP(D9,#REF!,3,0),0) -> 0 | BE9: =MAX(VLOOKUP(D9,#REF!,22,0)-VLOOKUP(D9,#REF!,23,0),0) -> #REF! | BF9: =BB9*BC9+BD9*BE9 -> #REF! | BG9: =BF9-BA9 -> #REF! | BH9: 0 | BK9: 2751 | BL9: =ROUNDUP(DI9/(1-0.17)*0.17,0) -> 2751 | BM9: =BL9-BK9 -> 0 | BN9: 0 | BR9: 0 | BT9: 0 | BV9: 0 | BX9: 101313.38 | BY9: =SUM(AE9,AH9,AN9,AR9,AU9,AY9,BA9,BH9,BK9,BN9,BR9,BT9) -> 101313.38 | BZ9: =BY9-BX9 -> 0 | CA9: 98562.38 | CB9: =SUM(AE9,AH9,BA9,BH9) -> 98562.38 | CC9: =CB9-CA9 -> 0 | CD9: 0 | CG9: 0 | CI9: 3189.041 | CJ9: 0 | CL9: 0 | CM9: 0.075 | CN9: 0 | CO9: 0 | CP9: 0 | CR9: 0 | CT9: 1500 | CU9: =MIN(BX9*5%,1500) -> 1500 | CV9: =CU9-CT9 -> 0 | CW9: 0 | CX9: =ROUND(CA9*CJ9,2) -> 0 | CY9: =CX9-CW9 -> 0 | CZ9: 1500 | DA9: =MIN(BX9*5%,1500) -> 1500 | DB9: =DA9-CZ9 -> 0 | DC9: 5892.18 | DD9: =MAX(ROUND(CA9*CM9-CZ9,2),0) -> 5892.18 | DE9: =DD9-DC9 -> 0 | DF9: 99813.38 | DG9: =SUM(AE9,AH9,AN9,AR9,AU9,AY9,BA9,BH9,BK9,BN9,BR9,BT9,BV9,-CG9,-CP9,-CT9,-CW9) -> 99813.38 | DH9: =DG9-DF9 -> 0 | DI9: 13427.55 | DJ9: =IFERROR(VLOOKUP(D9,#REF!,2,0),0) -> 0 | DK9: =DJ9-DI9 -> -13427.55 | DL9: 101313.38 | DM9: 1571135.6 | DN9: 8083.33 | DO9: 1562.38 | DP9: 0 | DQ9: 98562.38 | DR9: 28 | DS9: 0 | DT9: 2025-01-01 | DU9: 2025-12-31 | DV9: 2025-01-10 | DW9: 2025-02-10
A10: MSD Asia202502 | B10: MERCK SHARP & DOHME (ASIA) LIMITED | C10: MSD Asia | D10: 51447820 | E10: =VLOOKUP(D10,#REF!,1,0) -> #REF! | F10: Fong | G10: Hang Kit | H10: =G10&" "&F10 -> Hang Kit Fong | I10: =VLOOKUP(D10,#REF!,9,0) -> #REF! | J10: =I10=H10 -> #REF! | K10: Hang Kit | L10: Active | M10: 2022-11-14 | N10: =VLOOKUP(D10,#REF!,80,0) -> #REF! | O10: =N10-M10 -> #REF! | P10: MRL HKG GCTO | Q10: =VLOOKUP(D10,#REF!,50,0) -> #REF! | R10: =Q10=P10 -> #REF! | S10: Sr. CRA | T10: =VLOOKUP(D10,#REF!,21,0) -> #REF! | U10: =T10=S10 -> #REF! | V10: 12630167 | W10: =VLOOKUP(D10,#REF!,51,0) -> #REF! | X10: =W10=V10 -> #REF! | Y10: 202502 | Z10: N | AA10: 2.29 | AB10: 47819 | AC10: =ROUND(VLOOKUP(D10,#REF!,59,0),0) -> #REF! | AD10: =AC10-AB10 -> #REF! | AE10: 47819 | AF10: =AB10 -> 47819 | AG10: =AF10-AE10 -> 0 | AH10: 0 | AK10: 0 | AN10: 0 | AO10: 0 | AP10: =IFERROR(VLOOKUP('Feb for check'!D10,#REF!,15,0),0) -> 0 | AQ10: =AP10-AO10 -> 0 | AR10: 0 | AS10: =AO10 -> 0 | AT10: =AS10-AR10 -> 0 | AU10: 0 | AW10: 0 | AY10: 0 | BA10: 244.38 | BB10: =IFERROR(VLOOKUP(D10,#REF!,2,0),0) -> 0 | BC10: =MAX(VLOOKUP(D10,#REF!,13,0)-VLOOKUP(D10,#REF!,14,0),0) -> #REF! | BD10: =IFERROR(VLOOKUP(D10,#REF!,3,0),0) -> 0 | BE10: =MAX(VLOOKUP(D10,#REF!,22,0)-VLOOKUP(D10,#REF!,23,0),0) -> #REF! | BF10: =BB10*BC10+BD10*BE10 -> #REF! | BG10: =BF10-BA10 -> #REF! | BH10: 0 | BK10: 917 | BL10: =ROUNDUP(DI10/(1-0.17)*0.17,0) -> 917 | BM10: =BL10-BK10 -> 0 | BN10: 0 | BR10: 0 | BT10: 0 | BV10: 0 | BX10: 48980.38 | BY10: =SUM(AE10,AH10,AN10,AR10,AU10,AY10,BA10,BH10,BK10,BN10,BR10,BT10) -> 48980.38 | BZ10: =BY10-BX10 -> 0 | CA10: 48063.38 | CB10: =SUM(AE10,AH10,BA10,BH10) -> 48063.38 | CC10: =CB10-CA10 -> 0 | CD10: 0 | CG10: 0 | CI10: 1572.1315 | CJ10: 0 | CL10: 0 | CM10: 0.075 | CN10: 0 | CO10: 0 | CP10: 0 | CR10: 0 | CT10: 1500 | CU10: =MIN(BX10*5%,1500) -> 1500 | CV10: =CU10-CT10 -> 0 | CW10: 0 | CX10: =ROUND(CA10*CJ10,2) -> 0 | CY10: =CX10-CW10 -> 0 | CZ10: 1500 | DA10: =MIN(BX10*5%,1500) -> 1500 | DB10: =DA10-CZ10 -> 0 | DC10: 2104.75 | DD10: =MAX(ROUND(CA10*CM10-CZ10,2),0) -> 2104.75 | DE10: =DD10-DC10 -> 0 | DF10: 47480.38 | DG10: =SUM(AE10,AH10,AN10,AR10,AU10,AY10,BA10,BH10,BK10,BN10,BR10,BT10,BV10,-CG10,-CP10,-CT10,-CW10) -> 47480.38 | DH10: =DG10-DF10 -> 0 | DI10: 4475.85 | DJ10: =IFERROR(VLOOKUP(D10,#REF!,2,0),0) -> 0 | DK10: =DJ10-DI10 -> -4475.85 | DL10: 48980.38 | DM10: 811209.92 | DN10: 3984.92 | DO10: 244.38 | DP10: 0 | DQ10: 48063.38 | DR10: 28 | DS10: 0 | DT10: 2025-01-01 | DU10: 2025-12-31 | DV10: 2025-01-10 | DW10: 2025-02-10
A11: MSD Asia202502 | B11: MERCK SHARP & DOHME (ASIA) LIMITED | C11: MSD Asia | D11: 51302892 | E11: =VLOOKUP(D11,#REF!,1,0) -> #REF! | F11: Li | G11: Wing Ki | H11: =G11&" "&F11 -> Wing Ki Li | I11: =VLOOKUP(D11,#REF!,9,0) -> #REF! | J11: =I11=H11 -> #REF! | K11: Stella | L11: Active | M11: 2018-02-12 | N11: =VLOOKUP(D11,#REF!,80,0) -> #REF! | O11: =N11-M11 -> #REF! | P11: HK Public Sector Access | Q11: =VLOOKUP(D11,#REF!,50,0) -> #REF! | R11: =Q11=P11 -> #REF! | S11: Policy & Corporate Affairs Lead | T11: =VLOOKUP(D11,#REF!,21,0) -> #REF! | U11: =T11=S11 -> #REF! | V11: 12630108 | W11: =VLOOKUP(D11,#REF!,51,0) -> #REF! | X11: =W11=V11 -> #REF! | Y11: 202502 | Z11: N | AA11: 7.05 | AB11: 70390 | AC11: =ROUND(VLOOKUP(D11,#REF!,59,0),0) -> #REF! | AD11: =AC11-AB11 -> #REF! | AE11: 70390 | AF11: =AB11 -> 70390 | AG11: =AF11-AE11 -> 0 | AH11: 0 | AK11: 0 | AN11: 0 | AO11: 0 | AP11: =IFERROR(VLOOKUP('Feb for check'!D11,#REF!,15,0),0) -> 0 | AQ11: =AP11-AO11 -> 0 | AR11: 0 | AS11: =AO11 -> 0 | AT11: =AS11-AR11 -> 0 | AU11: 0 | AW11: 0 | AY11: 0 | BA11: 1837.22 | BB11: =IFERROR(VLOOKUP(D11,#REF!,2,0),0) -> 0 | BC11: =MAX(VLOOKUP(D11,#REF!,13,0)-VLOOKUP(D11,#REF!,14,0),0) -> #REF! | BD11: =IFERROR(VLOOKUP(D11,#REF!,3,0),0) -> 0 | BE11: =MAX(VLOOKUP(D11,#REF!,22,0)-VLOOKUP(D11,#REF!,23,0),0) -> #REF! | BF11: =BB11*BC11+BD11*BE11 -> #REF! | BG11: =BF11-BA11 -> #REF! | BH11: 0 | BK11: 917 | BL11: =ROUNDUP(DI11/(1-0.17)*0.17,0) -> 917 | BM11: =BL11-BK11 -> 0 | BN11: 0 | BR11: 0 | BT11: 0 | BV11: 0 | BX11: 73144.22 | BY11: =SUM(AE11,AH11,AN11,AR11,AU11,AY11,BA11,BH11,BK11,BN11,BR11,BT11) -> 73144.22 | BZ11: =BY11-BX11 -> 0 | CA11: 72227.22 | CB11: =SUM(AE11,AH11,BA11,BH11) -> 72227.22 | CC11: =CB11-CA11 -> 0 | CD11: 0 | CG11: 0 | CI11: 2314.1917 | CJ11: 0 | CL11: 0 | CM11: 0.075 | CN11: 0 | CO11: 0 | CP11: 0 | CR11: 0 | CT11: 1500 | CU11: =MIN(BX11*5%,1500) -> 1500 | CV11: =CU11-CT11 -> 0 | CW11: 0 | CX11: =ROUND(CA11*CJ11,2) -> 0 | CY11: =CX11-CW11 -> 0 | CZ11: 1500 | DA11: =MIN(BX11*5%,1500) -> 1500 | DB11: =DA11-CZ11 -> 0 | DC11: 3917.04 | DD11: =MAX(ROUND(CA11*CM11-CZ11,2),0) -> 3917.04 | DE11: =DD11-DC11 -> 0 | DF11: 71644.22 | DG11: =SUM(AE11,AH11,AN11,AR11,AU11,AY11,BA11,BH11,BK11,BN11,BR11,BT11,BV11,-CG11,-CP11,-CT11,-CW11) -> 71644.22 | DH11: =DG11-DF11 -> 0 | DI11: 4475.84 | DJ11: =IFERROR(VLOOKUP(D11,#REF!,2,0),0) -> 0 | DK11: =DJ11-DI11 -> -4475.84 | DL11: 73144.22 | DM11: 1195263.7 | DN11: 5865.83 | DO11: 1837.22 | DP11: 0 | DQ11: 72227.22 | DR11: 28 | DS11: 0 | DT11: 2025-01-01 | DU11: 2025-12-31 | DV11: 2025-01-10 | DW11: 2025-02-10
A12: MSD Asia202502 | B12: MERCK SHARP & DOHME (ASIA) LIMITED | C12: MSD Asia | D12: 51505904 | E12: =VLOOKUP(D12,#REF!,1,0) -> #REF! | F12: Tam | G12: Yin Kei | H12: =G12&" "&F12 -> Yin Kei Tam | I12: =VLOOKUP(D12,#REF!,9,0) -> #REF! | J12: =I12=H12 -> #REF! | K12: Yin Kei | L12: Active | M12: 2025-01-02 | N12: =VLOOKUP(D12,#REF!,80,0) -> #REF! | O12: =N12-M12 -> #REF! | P12: MRL HKG GRA INTL | Q12: =VLOOKUP(D12,#REF!,50,0) -> #REF! | R12: =Q12=P12 -> #REF! | S12: Regulatory Affairs Associate (Pharmacy Intern) | T12: =VLOOKUP(D12,#REF!,21,0) -> #REF! | U12: =T12=S12 -> #REF! | V12: 12630168 | W12: =VLOOKUP(D12,#REF!,51,0) -> #REF! | X12: =W12=V12 -> #REF! | Y12: 202502 | Z12: N | AA12: 0.16 | AB12: 0 | AE12: 0 | AH12: 0 | AK12: 13500 | AL12: =VLOOKUP(D12,#REF!,59,0) -> #REF! | AM12: =AL12-AK12 -> #REF! | AN12: 13500 | AO12: 0 | AP12: =IFERROR(VLOOKUP('Feb for check'!D12,#REF!,15,0),0) -> 0 | AQ12: =AP12-AO12 -> 0 | AR12: 0 | AS12: =AO12 -> 0 | AT12: =AS12-AR12 -> 0 | AU12: 0 | AW12: 0 | AY12: 0 | BA12: 0 | BB12: =IFERROR(VLOOKUP(D12,#REF!,2,0),0) -> 0 | BC12: =MAX(VLOOKUP(D12,#REF!,13,0)-VLOOKUP(D12,#REF!,14,0),0) -> #REF! | BD12: =IFERROR(VLOOKUP(D12,#REF!,3,0),0) -> 0 | BE12: =MAX(VLOOKUP(D12,#REF!,22,0)-VLOOKUP(D12,#REF!,23,0),0) -> #REF! | BF12: =BB12*BC12+BD12*BE12 -> #REF! | BG12: =BF12-BA12 -> #REF! | BH12: 0 | BK12: 0 | BL12: =ROUNDUP(DI12/(1-0.17)*0.17,0) -> 0 | BM12: =BL12-BK12 -> 0 | BN12: 0 | BR12: 0 | BT12: 0 | BV12: 0 | BX12: 13500 | BY12: =SUM(AE12,AH12,AN12,AR12,AU12,AY12,BA12,BH12,BK12,BN12,BR12,BT12) -> 13500 | BZ12: =BY12-BX12 -> 0 | CA12: 0 | CB12: =SUM(AE12,AH12,BA12,BH12) -> 0 | CC12: =CB12-CA12 -> 0 | CD12: 0 | CG12: 0 | CI12: 443.8356 | CJ12: 0 | CL12: 0 | CM12: 0 | CN12: 0 | CO12: 0 | CP12: 0 | CR12: 0 | CT12: 0 | CU12: =MIN(BX12*5%,1500) -> 675 | CV12: 新员工，未满60天不缴纳 | CW12: 0 | CX12: =ROUND(CA12*CJ12,2) -> 0 | CY12: =CX12-CW12 -> 0 | CZ12: 0 | DA12: =MIN(BX12*5%,1500) -> 675 | DB12: 新员工，未满60天不缴纳 | DC12: 0 | DD12: =MAX(ROUND(CA12*CM12-CZ12,2),0) -> 0 | DE12: =DD12-DC12 -> 0 | DF12: 13500 | DG12: =SUM(AE12,AH12,AN12,AR12,AU12,AY12,BA12,BH12,BK12,BN12,BR12,BT12,BV12,-CG12,-CP12,-CT12,-CW12) -> 13500 | DH12: =DG12-DF12 -> 0 | DI12: 0 | DJ12: =IFERROR(VLOOKUP(D12,#REF!,2,0),0) -> 0 | DK12: =DJ12-DI12 -> 0 | DL12: 13500 | DM12: 26564.52 | DN12: 1125 | DO12: 0 | DP12: 0 | DQ12: 13500 | DR12: 28 | DS12: 0 | DT12: 2025-01-02 | DU12: 2025-12-31 | DV12: 2025-01-10 | DW12: 2025-02-10
A13: MSD Asia202502 | B13: MERCK SHARP & DOHME (ASIA) LIMITED | C13: MSD Asia | D13: 10233093 | E13: =VLOOKUP(D13,#REF!,1,0) -> #REF! | F13: Wong | G13: Hoi Yan Pamela | H13: =G13&" "&F13 -> Hoi Yan Pamela Wong | I13: =VLOOKUP(D13,#REF!,9,0) -> #REF! | J13: =I13=H13 -> #REF! | K13: Pamela | L13: Active | M13: 2008-09-08 | N13: =VLOOKUP(D13,#REF!,80,0) -> #REF! | O13: =N13-M13 -> #REF! | P13: IT Global Infrastructure Operations - HK | Q13: =VLOOKUP(D13,#REF!,50,0) -> #REF! | R13: =Q13=P13 -> #REF! | S13: Director, Strategist, Foundational Platforms | T13: =VLOOKUP(D13,#REF!,21,0) -> #REF! | U13: =T13=S13 -> #REF! | V13: 12630026 | W13: =VLOOKUP(D13,#REF!,51,0) -> #REF! | X13: =W13=V13 -> #REF! | Y13: 202502 | Z13: N | AA13: 16.48 | AB13: 112137 | AC13: =ROUND(VLOOKUP(D13,#REF!,59,0),0) -> #REF! | AD13: =AC13-AB13 -> #REF! | AE13: 112137 | AF13: =AB13 -> 112137 | AG13: =AF13-AE13 -> 0 | AH13: 0 | AK13: 0 | AN13: 0 | AO13: 0 | AP13: =IFERROR(VLOOKUP('Feb for check'!D13,#REF!,15,0),0) -> 0 | AQ13: =AP13-AO13 -> 0 | AR13: 0 | AS13: =AO13 -> 0 | AT13: =AS13-AR13 -> 0 | AU13: 0 | AW13: 0 | AY13: 0 | BA13: 0 | BB13: =IFERROR(VLOOKUP(D13,#REF!,2,0),0) -> 0 | BC13: =MAX(VLOOKUP(D13,#REF!,13,0)-VLOOKUP(D13,#REF!,14,0),0) -> #REF! | BD13: =IFERROR(VLOOKUP(D13,#REF!,3,0),0) -> 0 | BE13: =MAX(VLOOKUP(D13,#REF!,22,0)-VLOOKUP(D13,#REF!,23,0),0) -> #REF! | BF13: =BB13*BC13+BD13*BE13 -> #REF! | BG13: =BF13-BA13 -> #REF! | BH13: 0 | BK13: 1540 | BL13: =ROUNDUP(DI13/(1-0.17)*0.17,0) -> 1540 | BM13: =BL13-BK13 -> 0 | BN13: 0 | BR13: 0 | BT13: 0 | BV13: 0 | BX13: 113677 | BY13: =SUM(AE13,AH13,AN13,AR13,AU13,AY13,BA13,BH13,BK13,BN13,BR13,BT13) -> 113677 | BZ13: =BY13-BX13 -> 0 | CA13: 112137 | CB13: =SUM(AE13,AH13,BA13,BH13) -> 112137 | CC13: =CB13-CA13 -> 0 | CD13: 0 | CG13: 0 | CI13: 3686.6958 | CJ13: 0.05 | CL13: 0 | CM13: 0.1 | CN13: 0 | CO13: 0 | CP13: 0 | CR13: 0 | CT13: 1500 | CU13: =MIN(BX13*5%,1500) -> 1500 | CV13: =CU13-CT13 -> 0 | CW13: 5606.85 | CX13: =ROUND(CA13*CJ13,2) -> 5606.85 | CY13: =CX13-CW13 -> 0 | CZ13: 1500 | DA13: =MIN(BX13*5%,1500) -> 1500 | DB13: =DA13-CZ13 -> 0 | DC13: 9713.7 | DD13: =MAX(ROUND(CA13*CM13-CZ13,2),0) -> 9713.7 | DE13: =DD13-DC13 -> 0 | DF13: 106570.15 | DG13: =SUM(AE13,AH13,AN13,AR13,AU13,AY13,BA13,BH13,BK13,BN13,BR13,BT13,BV13,-CG13,-CP13,-CT13,-CW13) -> 106570.15 | DH13: =DG13-DF13 -> 0 | DI13: 7518.08 | DJ13: =IFERROR(VLOOKUP(D13,#REF!,2,0),0) -> 0 | DK13: =DJ13-DI13 -> -7518.08 | DL13: 113677 | DM13: 2213744 | DN13: 9344.75 | DO13: 0 | DP13: 0 | DQ13: 112137 | DR13: 28 | DS13: 0 | DT13: 2025-01-01 | DU13: 2025-12-31 | DV13: 2025-01-10 | DW13: 2025-02-10
A14: MSD Asia202502 | B14: MERCK SHARP & DOHME (ASIA) LIMITED | C14: MSD Asia | D14: 51167064 | E14: =VLOOKUP(D14,#REF!,1,0) -> #REF! | F14: Lam | G14: Siu Yan | H14: =G14&" "&F14 -> Siu Yan Lam | I14: =VLOOKUP(D14,#REF!,9,0) -> #REF! | J14: =I14=H14 -> #REF! | K14: Sharon | L14: Active | M14: 2013-03-18 | N14: =VLOOKUP(D14,#REF!,80,0) -> #REF! | O14: =N14-M14 -> #REF! | P14: HK Direct Selling - Oncology | Q14: =VLOOKUP(D14,#REF!,50,0) -> #REF! | R14: =Q14=P14 -> #REF! | S14: Associate Sales Manager, Oncology | T14: =VLOOKUP(D14,#REF!,21,0) -> #REF! | U14: =T14=S14 -> #REF! | V14: 12630118 | W14: =VLOOKUP(D14,#REF!,51,0) -> #REF! | X14: =W14=V14 -> #REF! | Y14: 202502 | Z14: N | AA14: 11.95 | AB14: 45371 | AC14: =ROUND(VLOOKUP(D14,#REF!,59,0),0) -> #REF! | AD14: =AC14-AB14 -> #REF! | AE14: 45371 | AF14: =AB14 -> 45371 | AG14: =AF14-AE14 -> 0 | AH14: 0 | AK14: 0 | AN14: 0 | AO14: 2500 | AP14: =IFERROR(VLOOKUP('Feb for check'!D14,#REF!,15,0),0) -> 0 | AQ14: =AP14-AO14 -> -2500 | AR14: 2500 | AS14: =AO14 -> 2500 | AT14: =AS14-AR14 -> 0 | AU14: 0 | AW14: 0 | AY14: 0 | BA14: 2414.85 | BB14: =IFERROR(VLOOKUP(D14,#REF!,2,0),0) -> 0 | BC14: =MAX(VLOOKUP(D14,#REF!,13,0)-VLOOKUP(D14,#REF!,14,0),0) -> #REF! | BD14: =IFERROR(VLOOKUP(D14,#REF!,3,0),0) -> 0 | BE14: =MAX(VLOOKUP(D14,#REF!,22,0)-VLOOKUP(D14,#REF!,23,0),0) -> #REF! | BF14: =BB14*BC14+BD14*BE14 -> #REF! | BG14: =BF14-BA14 -> #REF! | BH14: 0 | BK14: 0 | BL14: =ROUNDUP(DI14/(1-0.17)*0.17,0) -> 0 | BM14: =BL14-BK14 -> 0 | BN14: 0 | BR14: 0 | BT14: 0 | BV14: 0 | BX14: 50285.85 | BY14: =SUM(AE14,AH14,AN14,AR14,AU14,AY14,BA14,BH14,BK14,BN14,BR14,BT14) -> 50285.85 | BZ14: =BY14-BX14 -> 0 | CA14: 47785.85 | CB14: =SUM(AE14,AH14,BA14,BH14) -> 47785.85 | CC14: =CB14-CA14 -> 0 | CD14: 0 | CG14: 0 | CI14: 1573.841 | CJ14: 0.05 | CL14: 0 | CM14: 0.1 | CN14: 0 | CO14: 0 | CP14: 0 | CR14: 0 | CT14: 1500 | CU14: =MIN(BX14*5%,1500) -> 1500 | CV14: =CU14-CT14 -> 0 | CW14: 2389.29 | CX14: =ROUND(CA14*CJ14,2) -> 2389.29 | CY14: =CX14-CW14 -> 0 | CZ14: 1500 | DA14: =MIN(BX14*5%,1500) -> 1500 | DB14: =DA14-CZ14 -> 0 | DC14: 3278.59 | DD14: =MAX(ROUND(CA14*CM14-CZ14,2),0) -> 3278.59 | DE14: =DD14-DC14 -> 0 | DF14: 46396.56 | DG14: =SUM(AE14,AH14,AN14,AR14,AU14,AY14,BA14,BH14,BK14,BN14,BR14,BT14,BV14,-CG14,-CP14,-CT14,-CW14) -> 46396.56 | DH14: =DG14-DF14 -> 0 | DI14: 0 | DJ14: =IFERROR(VLOOKUP(D14,#REF!,2,0),0) -> 0 | DK14: =DJ14-DI14 -> 0 | DL14: 47785.85 | DM14: 779433.25 | DN14: 3780.92 | DO14: 2414.85 | DP14: 0 | DQ14: 50285.85 | DR14: 28 | DS14: 0 | DT14: 2025-01-01 | DU14: 2025-12-31 | DV14: 2025-01-10 | DW14: 2025-02-10
A15: MSD Asia202502 | B15: MERCK SHARP & DOHME (ASIA) LIMITED | C15: MSD Asia | D15: 51445144 | E15: =VLOOKUP(D15,#REF!,1,0) -> #REF! | F15: Lin | G15: Nga Man | H15: =G15&" "&F15 -> Nga Man Lin | I15: =VLOOKUP(D15,#REF!,9,0) -> #REF! | J15: =I15=H15 -> #REF! | K15: Carman | L15: Active | M15: 2022-12-06 | N15: =VLOOKUP(D15,#REF!,80,0) -> #REF! | O15: =N15-M15 -> #REF! | P15: MRL HKG GCTO | Q15: =VLOOKUP(D15,#REF!,50,0) -> #REF! | R15: =Q15=P15 -> #REF! | S15: COM | T15: =VLOOKUP(D15,#REF!,21,0) -> #REF! | U15: =T15=S15 -> #REF! | V15: 12630167 | W15: =VLOOKUP(D15,#REF!,51,0) -> #REF! | X15: =W15=V15 -> #REF! | Y15: 202502 | Z15: N | AA15: 2.23 | AB15: 47493 | AC15: =ROUND(VLOOKUP(D15,#REF!,59,0),0) -> #REF! | AD15: =AC15-AB15 -> #REF! | AE15: 47493 | AF15: =AB15 -> 47493 | AG15: =AF15-AE15 -> 0 | AH15: 0 | AK15: 0 | AN15: 0 | AO15: 0 | AP15: =IFERROR(VLOOKUP('Feb for check'!D15,#REF!,15,0),0) -> 0 | AQ15: =AP15-AO15 -> 0 | AR15: 0 | AS15: =AO15 -> 0 | AT15: =AS15-AR15 -> 0 | AU15: 0 | AW15: 0 | AY15: 0 | BA15: 0 | BB15: =IFERROR(VLOOKUP(D15,#REF!,2,0),0) -> 0 | BC15: =MAX(VLOOKUP(D15,#REF!,13,0)-VLOOKUP(D15,#REF!,14,0),0) -> #REF! | BD15: =IFERROR(VLOOKUP(D15,#REF!,3,0),0) -> 0 | BE15: =MAX(VLOOKUP(D15,#REF!,22,0)-VLOOKUP(D15,#REF!,23,0),0) -> #REF! | BF15: =BB15*BC15+BD15*BE15 -> #REF! | BG15: =BF15-BA15 -> #REF! | BH15: 0 | BK15: 0 | BL15: =ROUNDUP(DI15/(1-0.17)*0.17,0) -> 0 | BM15: =BL15-BK15 -> 0 | BN15: 0 | BR15: 0 | BT15: 0 | BV15: 0 | BX15: 47493 | BY15: =SUM(AE15,AH15,AN15,AR15,AU15,AY15,BA15,BH15,BK15,BN15,BR15,BT15) -> 47493 | BZ15: =BY15-BX15 -> 0 | CA15: 47493 | CB15: =SUM(AE15,AH15,BA15,BH15) -> 47493 | CC15: =CB15-CA15 -> 0 | CD15: 0 | CG15: 0 | CI15: 1561.4136 | CJ15: 0 | CL15: 0 | CM15: 0.075 | CN15: 0 | CO15: 0 | CP15: 0 | CR15: 0 | CT15: 1500 | CU15: =MIN(BX15*5%,1500) -> 1500 | CV15: =CU15-CT15 -> 0 | CW15: 0 | CX15: =ROUND(CA15*CJ15,2) -> 0 | CY15: =CX15-CW15 -> 0 | CZ15: 1500 | DA15: =MIN(BX15*5%,1500) -> 1500 | DB15: =DA15-CZ15 -> 0 | DC15: 2061.98 | DD15: =MAX(ROUND(CA15*CM15-CZ15,2),0) -> 2061.98 | DE15: =DD15-DC15 -> 0 | DF15: 45993 | DG15: =SUM(AE15,AH15,AN15,AR15,AU15,AY15,BA15,BH15,BK15,BN15,BR15,BT15,BV15,-CG15,-CP15,-CT15,-CW15) -> 45993 | DH15: =DG15-DF15 -> 0 | DI15: 0 | DJ15: =IFERROR(VLOOKUP(D15,#REF!,2,0),0) -> 0 | DK15: =DJ15-DI15 -> 0 | DL15: 47493 | DM15: 796842.14 | DN15: 3957.75 | DO15: 0 | DP15: 0 | DQ15: 47493 | DR15: 28 | DS15: 0 | DT15: 2025-01-01 | DU15: 2025-12-31 | DV15: 2025-01-10 | DW15: 2025-02-10
A16: MSD Asia202502 | B16: MERCK SHARP & DOHME (ASIA) LIMITED | C16: MSD Asia | D16: 51490540 | E16: =VLOOKUP(D16,#REF!,1,0) -> #REF! | F16: Wan | G16: Woon See Claudia | H16: =G16&" "&F16 -> Woon See Claudia Wan | I16: =VLOOKUP(D16,#REF!,9,0) -> #REF! | J16: =I16=H16 -> #REF! | L16: Active | M16: 2024-05-13 | N16: =VLOOKUP(D16,#REF!,80,0) -> #REF! | O16: =N16-M16 -> #REF! | P16: MRL HKG GCTO | Q16: =VLOOKUP(D16,#REF!,50,0) -> #REF! | R16: =Q16=P16 -> #REF! | S16: CTC | T16: =VLOOKUP(D16,#REF!,21,0) -> #REF! | U16: =T16=S16 -> #REF! | V16: 12630167 | W16: =VLOOKUP(D16,#REF!,51,0) -> #REF! | X16: =W16=V16 -> #REF! | Y16: 202502 | Z16: N | AA16: 0.8 | AB16: 29000 | AC16: =ROUND(VLOOKUP(D16,#REF!,59,0),0) -> #REF! | AD16: =AC16-AB16 -> #REF! | AE16: 29000 | AF16: =AB16 -> 29000 | AG16: =AF16-AE16 -> 0 | AH16: 0 | AK16: 0 | AN16: 0 | AO16: 0 | AP16: =IFERROR(VLOOKUP('Feb for check'!D16,#REF!,15,0),0) -> 0 | AQ16: =AP16-AO16 -> 0 | AR16: 0 | AS16: =AO16 -> 0 | AT16: =AS16-AR16 -> 0 | AU16: 0 | AW16: 0 | AY16: 0 | BA16: 0 | BB16: =IFERROR(VLOOKUP(D16,#REF!,2,0),0) -> 0 | BC16: =MAX(VLOOKUP(D16,#REF!,13,0)-VLOOKUP(D16,#REF!,14,0),0) -> #REF! | BD16: =IFERROR(VLOOKUP(D16,#REF!,3,0),0) -> 0 | BE16: =MAX(VLOOKUP(D16,#REF!,22,0)-VLOOKUP(D16,#REF!,23,0),0) -> #REF! | BF16: =BB16*BC16+BD16*BE16 -> #REF! | BG16: =BF16-BA16 -> #REF! | BH16: 0 | BK16: 0 | BL16: =ROUNDUP(DI16/(1-0.17)*0.17,0) -> 0 | BM16: =BL16-BK16 -> 0 | BN16: 0 | BR16: 0 | BT16: 0 | BV16: 0 | BX16: 29000 | BY16: =SUM(AE16,AH16,AN16,AR16,AU16,AY16,BA16,BH16,BK16,BN16,BR16,BT16) -> 29000 | BZ16: =BY16-BX16 -> 0 | CA16: 29000 | CB16: =SUM(AE16,AH16,BA16,BH16) -> 29000 | CC16: =CB16-CA16 -> 0 | CD16: 0 | CG16: 0 | CI16: 953.4246 | CJ16: 0 | CL16: 0 | CM16: 0.075 | CN16: 0 | CO16: 0 | CP16: 0 | CR16: 0 | CT16: 1450 | CU16: =MIN(BX16*5%,1500) -> 1450 | CV16: =CU16-CT16 -> 0 | CW16: 0 | CX16: =ROUND(CA16*CJ16,2) -> 0 | CY16: =CX16-CW16 -> 0 | CZ16: 1450 | DA16: =MIN(BX16*5%,1500) -> 1450 | DB16: =DA16-CZ16 -> 0 | DC16: 725 | DD16: =MAX(ROUND(CA16*CM16-CZ16,2),0) -> 725 | DE16: =DD16-DC16 -> 0 | DF16: 27550 | DG16: =SUM(AE16,AH16,AN16,AR16,AU16,AY16,BA16,BH16,BK16,BN16,BR16,BT16,BV16,-CG16,-CP16,-CT16,-CW16) -> 27550 | DH16: =DG16-DF16 -> 0 | DI16: 0 | DJ16: =IFERROR(VLOOKUP(D16,#REF!,2,0),0) -> 0 | DK16: =DJ16-DI16 -> 0 | DL16: 29000 | DM16: 297797.81 | DN16: 2416.67 | DO16: 0 | DP16: 0 | DQ16: 29000 | DR16: 28 | DS16: 0 | DT16: 2025-01-01 | DU16: 2025-12-31 | DV16: 2025-01-10 | DW16: 2025-02-10
A17: MSD Asia202502 | B17: MERCK SHARP & DOHME (ASIA) LIMITED | C17: MSD Asia | D17: 51090149 | E17: =VLOOKUP(D17,#REF!,1,0) -> #REF! | F17: Iu | G17: Hoi Yan | H17: =G17&" "&F17 -> Hoi Yan Iu | I17: =VLOOKUP(D17,#REF!,9,0) -> #REF! | J17: =I17=H17 -> #REF! | K17: Orlean | L17: Active | M17: 2011-12-12 | N17: =VLOOKUP(D17,#REF!,80,0) -> #REF! | O17: =N17-M17 -> #REF! | P17: MRL HKG GRA INTL | Q17: =VLOOKUP(D17,#REF!,50,0) -> #REF! | R17: =Q17=P17 -> #REF! | S17: Regulatory Affairs Manager | T17: =VLOOKUP(D17,#REF!,21,0) -> #REF! | U17: =T17=S17 -> #REF! | V17: 12630168 | W17: =VLOOKUP(D17,#REF!,51,0) -> #REF! | X17: =W17=V17 -> #REF! | Y17: 202502 | Z17: N | AA17: 13.22 | AB17: 55161 | AC17: =ROUND(VLOOKUP(D17,#REF!,59,0),0) -> #REF! | AD17: =AC17-AB17 -> #REF! | AE17: 55161 | AF17: =AB17 -> 55161 | AG17: =AF17-AE17 -> 0 | AH17: 0 | AK17: 0 | AN17: 0 | AO17: 0 | AP17: =IFERROR(VLOOKUP('Feb for check'!D17,#REF!,15,0),0) -> 0 | AQ17: =AP17-AO17 -> 0 | AR17: 0 | AS17: =AO17 -> 0 | AT17: =AS17-AR17 -> 0 | AU17: 0 | AW17: 0 | AY17: 0 | BA17: 299.6 | BB17: =IFERROR(VLOOKUP(D17,#REF!,2,0),0) -> 0 | BC17: =MAX(VLOOKUP(D17,#REF!,13,0)-VLOOKUP(D17,#REF!,14,0),0) -> #REF! | BD17: =IFERROR(VLOOKUP(D17,#REF!,3,0),0) -> 0 | BE17: =MAX(VLOOKUP(D17,#REF!,22,0)-VLOOKUP(D17,#REF!,23,0),0) -> #REF! | BF17: =BB17*BC17+BD17*BE17 -> #REF! | BG17: =BF17-BA17 -> #REF! | BH17: 0 | BK17: 0 | BL17: =ROUNDUP(DI17/(1-0.17)*0.17,0) -> 0 | BM17: =BL17-BK17 -> 0 | BN17: 0 | BR17: 0 | BT17: 0 | BV17: 0 | BX17: 55460.6 | BY17: =SUM(AE17,AH17,AN17,AR17,AU17,AY17,BA17,BH17,BK17,BN17,BR17,BT17) -> 55460.6 | BZ17: =BY17-BX17 -> 0 | CA17: 55460.6 | CB17: =SUM(AE17,AH17,BA17,BH17) -> 55460.6 | CC17: =CB17-CA17 -> 0 | CD17: 0 | CG17: 0 | CI17: 1813.5123 | CJ17: 0 | CL17: 0 | CM17: 0.075 | CN17: 0 | CO17: 0 | CP17: 0 | CR17: 0 | CT17: 1500 | CU17: =MIN(BX17*5%,1500) -> 1500 | CV17: =CU17-CT17 -> 0 | CW17: 0 | CX17: =ROUND(CA17*CJ17,2) -> 0 | CY17: =CX17-CW17 -> 0 | CZ17: 1500 | DA17: =MIN(BX17*5%,1500) -> 1500 | DB17: =DA17-CZ17 -> 0 | DC17: 2659.55 | DD17: =MAX(ROUND(CA17*CM17-CZ17,2),0) -> 2659.55 | DE17: =DD17-DC17 -> 0 | DF17: 53960.6 | DG17: =SUM(AE17,AH17,AN17,AR17,AU17,AY17,BA17,BH17,BK17,BN17,BR17,BT17,BV17,-CG17,-CP17,-CT17,-CW17) -> 53960.6 | DH17: =DG17-DF17 -> 0 | DI17: 0 | DJ17: =IFERROR(VLOOKUP(D17,#REF!,2,0),0) -> 0 | DK17: =DJ17-DI17 -> 0 | DL17: 55460.6 | DM17: 947197.43 | DN17: 4596.75 | DO17: 299.6 | DP17: 0 | DQ17: 55460.6 | DR17: 28 | DS17: 0 | DT17: 2025-01-01 | DU17: 2025-12-31 | DV17: 2025-01-10 | DW17: 2025-02-10
A18: MSD Asia202502 | B18: MERCK SHARP & DOHME (ASIA) LIMITED | C18: MSD Asia | D18: 51477071 | E18: =VLOOKUP(D18,#REF!,1,0) -> #REF! | F18: Choi | G18: Ching Ha Pamela | H18: =G18&" "&F18 -> Ching Ha Pamela Choi | I18: =VLOOKUP(D18,#REF!,9,0) -> #REF! | J18: =I18=H18 -> #REF! | K18: Pamela | L18: Active | M18: 2024-01-02 | N18: =VLOOKUP(D18,#REF!,80,0) -> #REF! | O18: =N18-M18 -> #REF! | P18: MRL HKG GRA INTL | Q18: =VLOOKUP(D18,#REF!,50,0) -> #REF! | R18: =Q18=P18 -> #REF! | S18: Senior Regulatory Affairs Associate | T18: =VLOOKUP(D18,#REF!,21,0) -> #REF! | U18: =T18=S18 -> #REF! | V18: 12630168 | W18: =VLOOKUP(D18,#REF!,51,0) -> #REF! | X18: =W18=V18 -> #REF! | Y18: 202502 | Z18: N | AA18: 1.16 | AB18: 34000 | AC18: =ROUND(VLOOKUP(D18,#REF!,59,0),0) -> #REF! | AD18: =AC18-AB18 -> #REF! | AE18: 34000 | AF18: =AB18 -> 34000 | AG18: =AF18-AE18 -> 0 | AH18: 0 | AK18: 0 | AN18: 0 | AO18: 0 | AP18: =IFERROR(VLOOKUP('Feb for check'!D18,#REF!,15,0),0) -> 0 | AQ18: =AP18-AO18 -> 0 | AR18: 0 | AS18: =AO18 -> 0 | AT18: =AS18-AR18 -> 0 | AU18: 0 | AW18: 0 | AY18: 0 | BA18: 9.46 | BB18: =IFERROR(VLOOKUP(D18,#REF!,2,0),0) -> 0 | BC18: =MAX(VLOOKUP(D18,#REF!,13,0)-VLOOKUP(D18,#REF!,14,0),0) -> #REF! | BD18: =IFERROR(VLOOKUP(D18,#REF!,3,0),0) -> 0 | BE18: =MAX(VLOOKUP(D18,#REF!,22,0)-VLOOKUP(D18,#REF!,23,0),0) -> #REF! | BF18: =BB18*BC18+BD18*BE18 -> #REF! | BG18: =BF18-BA18 -> #REF! | BH18: 0 | BK18: 221 | BL18: =ROUNDUP(DI18/(1-0.17)*0.17,0) -> 221 | BM18: =BL18-BK18 -> 0 | BN18: 0 | BR18: 0 | BT18: 0 | BV18: 0 | BX18: 34230.46 | BY18: =SUM(AE18,AH18,AN18,AR18,AU18,AY18,BA18,BH18,BK18,BN18,BR18,BT18) -> 34230.46 | BZ18: =BY18-BX18 -> 0 | CA18: 34009.46 | CB18: =SUM(AE18,AH18,BA18,BH18) -> 34009.46 | CC18: =CB18-CA18 -> 0 | CD18: 0 | CG18: 0 | CI18: 1117.8082 | CJ18: 0 | CL18: 0 | CM18: 0.075 | CN18: 0 | CO18: 0 | CP18: 0 | CR18: 0 | CT18: 1500 | CU18: =MIN(BX18*5%,1500) -> 1500 | CV18: =CU18-CT18 -> 0 | CW18: 0 | CX18: =ROUND(CA18*CJ18,2) -> 0 | CY18: =CX18-CW18 -> 0 | CZ18: 1500 | DA18: =MIN(BX18*5%,1500) -> 1500 | DB18: =DA18-CZ18 -> 0 | DC18: 1050.71 | DD18: =MAX(ROUND(CA18*CM18-CZ18,2),0) -> 1050.71 | DE18: =DD18-DC18 -> 0 | DF18: 32730.46 | DG18: =SUM(AE18,AH18,AN18,AR18,AU18,AY18,BA18,BH18,BK18,BN18,BR18,BT18,BV18,-CG18,-CP18,-CT18,-CW18) -> 32730.46 | DH18: =DG18-DF18 -> 0 | DI18: 1076.14 | DJ18: =IFERROR(VLOOKUP(D18,#REF!,2,0),0) -> 0 | DK18: =DJ18-DI18 -> -1076.14 | DL18: 34230.46 | DM18: 443189.37 | DN18: 2833.33 | DO18: 9.46 | DP18: 0 | DQ18: 34009.46 | DR18: 28 | DS18: 0 | DT18: 2025-01-01 | DU18: 2025-12-31 | DV18: 2025-01-10 | DW18: 2025-02-10
A19: MSD Asia202502 | B19: MERCK SHARP & DOHME (ASIA) LIMITED | C19: MSD Asia | D19: 33900076 | E19: =VLOOKUP(D19,#REF!,1,0) -> #REF! | F19: Chu | G19: Wai Kwan Agnes | H19: =G19&" "&F19 -> Wai Kwan Agnes Chu | I19: =VLOOKUP(D19,#REF!,9,0) -> #REF! | J19: =I19=H19 -> #REF! | K19: Agnes | L19: Active | M19: 1992-01-06 | N19: =VLOOKUP(D19,#REF!,80,0) -> #REF! | O19: Follow Payroll system date | P19: Distribution & Logistics - HK | Q19: =VLOOKUP(D19,#REF!,50,0) -> #REF! | R19: =Q19=P19 -> #REF! | S19: SCM Lead, Hong Kong | T19: =VLOOKUP(D19,#REF!,21,0) -> #REF! | U19: =T19=S19 -> #REF! | V19: 12630165 | W19: =VLOOKUP(D19,#REF!,51,0) -> #REF! | X19: =W19=V19 -> #REF! | Y19: 202502 | Z19: N | AA19: 33.15 | AB19: 61865 | AC19: =ROUND(VLOOKUP(D19,#REF!,59,0),0) -> #REF! | AD19: =AC19-AB19 -> #REF! | AE19: 61865 | AF19: =AB19 -> 61865 | AG19: =AF19-AE19 -> 0 | AH19: 0 | AK19: 0 | AN19: 0 | AO19: 0 | AP19: =IFERROR(VLOOKUP('Feb for check'!D19,#REF!,15,0),0) -> 0 | AQ19: =AP19-AO19 -> 0 | AR19: 0 | AS19: =AO19 -> 0 | AT19: =AS19-AR19 -> 0 | AU19: 0 | AW19: 0 | AY19: 0 | BA19: 4322.34 | BB19: =IFERROR(VLOOKUP(D19,#REF!,2,0),0) -> 0 | BC19: =MAX(VLOOKUP(D19,#REF!,13,0)-VLOOKUP(D19,#REF!,14,0),0) -> #REF! | BD19: =IFERROR(VLOOKUP(D19,#REF!,3,0),0) -> 0 | BE19: =MAX(VLOOKUP(D19,#REF!,22,0)-VLOOKUP(D19,#REF!,23,0),0) -> #REF! | BF19: =BB19*BC19+BD19*BE19 -> #REF! | BG19: =BF19-BA19 -> #REF! | BH19: 0 | BK19: 0 | BL19: =ROUNDUP(DI19/(1-0.17)*0.17,0) -> 0 | BM19: =BL19-BK19 -> 0 | BN19: 0 | BR19: 0 | BT19: 0 | BV19: 0 | BX19: 0 | CA19: 0 | CD19: 61865 | CE19: =AE19 -> 61865 | CF19: =CE19-CD19 -> 0 | CG19: 0 | CI19: 2033.9178 | CJ19: 0 | CL19: 0 | CM19: 0 | CN19: 0.05 | CO19: 0.061 | CP19: 3093.25 | CQ19: =ROUND(CN19*CD19,2) -> 3093.25 | CR19: 3773.77 | CS19: =ROUND(CD19*CO19,2) -> 3773.77 | CT19: 0 | CW19: 0 | CX19: =ROUND(CA19*CJ19,2) -> 0 | CY19: =CX19-CW19 -> 0 | CZ19: 0 | DA19: =MIN(BX19*5%,1500) -> 0 | DB19: =DA19-CZ19 -> 0 | DC19: 0 | DD19: =MAX(ROUND(CA19*CM19-CZ19,2),0) -> 0 | DE19: =DD19-DC19 -> 0 | DF19: 63094.09 | DG19: =SUM(AE19,AH19,AN19,AR19,AU19,AY19,BA19,BH19,BK19,BN19,BR19,BT19,BV19,-CG19,-CP19,-CT19,-CW19) -> 63094.09 | DH19: =DG19-DF19 -> 0 | DI19: 0 | DJ19: =IFERROR(VLOOKUP(D19,#REF!,2,0),0) -> 0 | DK19: =DJ19-DI19 -> 0 | DL19: 66187.34 | DM19: 1046341.6 | DN19: 5155.42 | DO19: 4322.34 | DP19: 54.94 | DQ19: 66187.34 | DR19: 28 | DS19: 0 | DT19: 2025-01-01 | DU19: 2025-12-31 | DV19: 2025-01-10 | DW19: 2025-02-10
A20: MSD Asia202502 | B20: MERCK SHARP & DOHME (ASIA) LIMITED | C20: MSD Asia | D20: 51443693 | E20: =VLOOKUP(D20,#REF!,1,0) -> #REF! | F20: Tse | G20: Wai ling | H20: =G20&" "&F20 -> Wai ling Tse | I20: =VLOOKUP(D20,#REF!,9,0) -> #REF! | J20: =I20=H20 -> #REF! | K20: Elva | L20: Active | M20: 2022-09-26 | N20: =VLOOKUP(D20,#REF!,80,0) -> #REF! | O20: =N20-M20 -> #REF! | P20: CAS-HONG KONG | Q20: =VLOOKUP(D20,#REF!,50,0) -> #REF! | R20: =Q20=P20 -> #REF! | S20: Specialist - Solutions, Decision Science, HHDDA- Asia Pacific | T20: =VLOOKUP(D20,#REF!,21,0) -> #REF! | U20: =T20=S20 -> #REF! | V20: 12630420 | W20: =VLOOKUP(D20,#REF!,51,0) -> #REF! | X20: =W20=V20 -> #REF! | Y20: 202502 | Z20: N | AA20: 2.43 | AB20: 45292.85 | AC20: =ROUND(VLOOKUP(D20,#REF!,59,0),0) -> #REF! | AD20: =AC20-AB20 -> #REF! | AE20: 46611.7 | AF20: =AB20+AB20-VLOOKUP(D20,#REF!,14,0) -> #REF! | AG20: =AF20-AE20 -> #REF! | AH20: 0 | AK20: 0 | AN20: 0 | AO20: 0 | AP20: =IFERROR(VLOOKUP('Feb for check'!D20,#REF!,15,0),0) -> 0 | AQ20: =AP20-AO20 -> 0 | AR20: 0 | AS20: =AO20 -> 0 | AT20: =AS20-AR20 -> 0 | AU20: 0 | AW20: 0 | AY20: 0 | BA20: 2160.21 | BB20: =IFERROR(VLOOKUP(D20,#REF!,2,0),0) -> 0 | BC20: =MAX(VLOOKUP(D20,#REF!,13,0)-VLOOKUP(D20,#REF!,14,0),0) -> #REF! | BD20: =IFERROR(VLOOKUP(D20,#REF!,3,0),0) -> 0 | BE20: =MAX(VLOOKUP(D20,#REF!,22,0)-VLOOKUP(D20,#REF!,23,0),0) -> #REF! | BF20: =BB20*BC20+BD20*BE20 -> #REF! | BG20: =BF20-BA20 -> #REF! | BH20: 0 | BK20: 0 | BL20: =ROUNDUP(DI20/(1-0.17)*0.17,0) -> 0 | BM20: =BL20-BK20 -> 0 | BN20: 0 | BR20: 0 | BT20: 0 | BV20: 0 | BX20: 48771.91 | BY20: =SUM(AE20,AH20,AN20,AR20,AU20,AY20,BA20,BH20,BK20,BN20,BR20,BT20) -> 48771.91 | BZ20: =BY20-BX20 -> 0 | CA20: 48771.91 | CB20: =SUM(AE20,AH20,BA20,BH20) -> 48771.91 | CC20: =CB20-CA20 -> 0 | CD20: 0 | CG20: 0 | CI20: 1445.7205 | CJ20: 0 | CL20: 0 | CM20: 0.075 | CN20: 0 | CO20: 0 | CP20: 0 | CR20: 0 | CT20: 1500 | CU20: =MIN(BX20*5%,1500) -> 1500 | CV20: =CU20-CT20 -> 0 | CW20: 0 | CX20: =ROUND(CA20*CJ20,2) -> 0 | CY20: =CX20-CW20 -> 0 | CZ20: 1500 | DA20: =MIN(BX20*5%,1500) -> 1500 | DB20: =DA20-CZ20 -> 0 | DC20: 2157.89 | DD20: =MAX(ROUND(CA20*CM20-CZ20,2),0) -> 2157.89 | DE20: =DD20-DC20 -> 0 | DF20: 47271.91 | DG20: =SUM(AE20,AH20,AN20,AR20,AU20,AY20,BA20,BH20,BK20,BN20,BR20,BT20,BV20,-CG20,-CP20,-CT20,-CW20) -> 47271.91 | DH20: =DG20-DF20 -> 0 | DI20: 0 | DJ20: =IFERROR(VLOOKUP(D20,#REF!,2,0),0) -> 0 | DK20: =DJ20-DI20 -> 0 | DL20: 48771.91 | DM20: 696251.17 | DN20: 3774.4 | DO20: 2160.21 | DP20: 0 | DQ20: 48771.91 | DR20: 28 | DS20: 0 | DT20: 2025-01-01 | DU20: 2025-12-31 | DV20: 2025-01-10 | DW20: 2025-02-10
A21: MSD Asia202502 | B21: MERCK SHARP & DOHME (ASIA) LIMITED | C21: MSD Asia | D21: 51430650 | E21: =VLOOKUP(D21,#REF!,1,0) -> #REF! | F21: Leung | G21: Sze Ching | H21: =G21&" "&F21 -> Sze Ching Leung | I21: =VLOOKUP(D21,#REF!,9,0) -> #REF! | J21: =I21=H21 -> #REF! | K21: Natalie | L21: Active | M21: 2022-06-13 | N21: =VLOOKUP(D21,#REF!,80,0) -> #REF! | O21: =N21-M21 -> #REF! | P21: HK Direct Selling - Oncology | Q21: =VLOOKUP(D21,#REF!,50,0) -> #REF! | R21: =Q21=P21 -> #REF! | S21: Customer Rep., Sales ONC | T21: =VLOOKUP(D21,#REF!,21,0) -> #REF! | U21: =T21=S21 -> #REF! | V21: 12630118 | W21: =VLOOKUP(D21,#REF!,51,0) -> #REF! | X21: =W21=V21 -> #REF! | Y21: 202502 | Z21: N | AA21: 2.72 | AB21: 27500 | AC21: =ROUND(VLOOKUP(D21,#REF!,59,0),0) -> #REF! | AD21: =AC21-AB21 -> #REF! | AE21: 27500 | AF21: =AB21 -> 27500 | AG21: =AF21-AE21 -> 0 | AH21: 0 | AK21: 0 | AN21: 0 | AO21: 2500 | AP21: =IFERROR(VLOOKUP('Feb for check'!D21,#REF!,15,0),0) -> 0 | AQ21: =AP21-AO21 -> -2500 | AR21: 2500 | AS21: =AO21 -> 2500 | AT21: =AS21-AR21 -> 0 | AU21: 0 | AW21: 0 | AY21: 0 | BA21: 0 | BB21: =IFERROR(VLOOKUP(D21,#REF!,2,0),0) -> 0 | BC21: =MAX(VLOOKUP(D21,#REF!,13,0)-VLOOKUP(D21,#REF!,14,0),0) -> #REF! | BD21: =IFERROR(VLOOKUP(D21,#REF!,3,0),0) -> 0 | BE21: =MAX(VLOOKUP(D21,#REF!,22,0)-VLOOKUP(D21,#REF!,23,0),0) -> #REF! | BF21: =BB21*BC21+BD21*BE21 -> #REF! | BG21: =BF21-BA21 -> #REF! | BH21: 0 | BK21: 276 | BL21: =ROUNDUP(DI21/(1-0.17)*0.17,0) -> 276 | BM21: =BL21-BK21 -> 0 | BN21: 0 | BR21: 0 | BT21: 0 | BV21: 0 | BX21: 30276 | BY21: =SUM(AE21,AH21,AN21,AR21,AU21,AY21,BA21,BH21,BK21,BN21,BR21,BT21) -> 30276 | BZ21: =BY21-BX21 -> 0 | CA21: 27500 | CB21: =SUM(AE21,AH21,BA21,BH21) -> 27500 | CC21: =CB21-CA21 -> 0 | CD21: 0 | CG21: 0 | CI21: 986.3013 | CJ21: 0 | CL21: 0 | CM21: 0.075 | CN21: 0 | CO21: 0 | CP21: 0 | CR21: 0 | CT21: 1500 | CU21: =MIN(BX21*5%,1500) -> 1500 | CV21: =CU21-CT21 -> 0 | CW21: 0 | CX21: =ROUND(CA21*CJ21,2) -> 0 | CY21: =CX21-CW21 -> 0 | CZ21: 1500 | DA21: =MIN(BX21*5%,1500) -> 1500 | DB21: =DA21-CZ21 -> 0 | DC21: 562.5 | DD21: =MAX(ROUND(CA21*CM21-CZ21,2),0) -> 562.5 | DE21: =DD21-DC21 -> 0 | DF21: 28776 | DG21: =SUM(AE21,AH21,AN21,AR21,AU21,AY21,BA21,BH21,BK21,BN21,BR21,BT21,BV21,-CG21,-CP21,-CT21,-CW21) -> 28776 | DH21: =DG21-DF21 -> 0 | DI21: 1344.24 | DJ21: =IFERROR(VLOOKUP(D21,#REF!,2,0),0) -> 0 | DK21: =DJ21-DI21 -> -1344.24 | DL21: 27776 | DM21: 474904.41 | DN21: 2291.67 | DO21: 0 | DP21: 0 | DQ21: 30000 | DR21: 28 | DS21: 0 | DT21: 2025-01-01 | DU21: 2025-12-31 | DV21: 2025-01-10 | DW21: 2025-02-10
